Workbook

Sheet Cases2021 2022 FC
A1: Global Business Unit | B1: FS Greece
A2: Customer Channel Code | B2: Total National1900
A3: Customer Channel Code | B3: All
A4: Product.European Category Hierarchy | B4: All | AG4: 2025
A5: Bom Flag | B5: BOM Header + BOM Single
A6: Date Month View | B6: (Multiple Items) | AG6: 2024 FC based on FY PLAN
AG7: Q1 | AJ7: Q2 | AM7: Q3 | AP7: Q4
A8: Case | D8: Year | E8: Month | AC8: MRDR | AD8: Average 3mhnoy | AE8: Average 6mhnoy | AG8: 1 | AH8: 1 | AI8: 1 | AJ8: 1 | AK8: 1 | AL8: 1 | AM8: 1 | AN8: 1 | AO8: 1 | AP8: 1 | AQ8: 1 | AR8: 1
D9: 2024 | E9: 2024 | F9: 2024 | G9: 2024 | H9: 2024 | I9: 2024 | J9: 2024 | K9: 2024 | L9: 2024 | M9: 2024 | N9: 2024 | O9: 2024 | P9: 2025 | Q9: 2025 | R9: 2025 | S9: 2025 | T9: 2025 | U9: 2025 | V9: 2025 | W9: 2025 | X9: 2025 | Y9: 2025 | Z9: 2025 | AG9: 1 | AH9: 2 | AI9: 3 | AJ9: 4 | AK9: 5 | AL9: 6 | AM9: 7 | AN9: 8 | AO9: 9 | AP9: 10 | AQ9: 11 | AR9: 12
A10: Category | B10: SKU Code | C10: Product Country Specific Language 1 | D10: 1 | E10: 2 | F10: 3 | G10: 4 | H10: 5 | I10: 6 | J10: 7 | K10: 8 | L10: 9 | M10: 10 | N10: 11 | O10: 12 | P10: 1 | Q10: 2 | R10: 3 | S10: 4 | T10: 5 | U10: 6 | V10: 7 | W10: 8 | X10: 9 | Y10: 10 | Z10: 11
A11: CONDIMENT | B11: 000000000010865401 | C11: HELLMANN'S ΝΤΡΕΣΙΝΓΚ ΜΕΛΙ&ΜΟΥΣΤΑΡΔΑ 6Χ1Λ | D11: -1.167 | E11: -19.001 | F11: -0.5 | G11: -2 | H11: -0.167 | I11: 0 | J11: -1.001 | K11: -0.333 | L11: -0.334 | M11: -10.333 | N11: -0.334 | O11: -0.333 | P11: -39.834 | Q11: -53.5 | R11: -0.167 | S11: -4.666 | T11: -75.333 | U11: -14.833 | V11: -15.667 | W11: -39 | X11: -18.999 | Y11: -11 | Z11: -70.334 | AC11: =VALUE(TEXT(B11,0)) -> 10865401 | AD11: {=ROUND(AVERAGE(AP11:AR11/25),0)} -> -1 | AE11: {=ROUND(AVERAGE(AM11:AR11/25),0)} -> -1 | AG11: =ROUND(P11*AG$8,0) -> -40 | AH11: =ROUND(Q11*AH$8,0) -> -54 | AI11: =ROUND(R11*AI$8,0) -> 0 | AJ11: =ROUND(S11*AJ$8,0) -> -5 | AK11: =ROUND(T11*AK$8,0) -> -75 | AL11: =ROUND(U11*AL$8,0) -> -15 | AM11: =ROUND(V11*AM$8,0) -> -16 | AN11: =ROUND(W11*AN$8,0) -> -39 | ... AQ11: =ROUND(Z11*AQ$8,0) -> -70 | AR11: =ROUND(O11*AR$8,0) -> 0
A12: CONDIMENT | B12: 000000000012100503 | C12: HLMNS ΜΑΓΙΟΝΕΖΑ REAL 10Λ | D12: 10335 | E12: 8263 | F12: 8272 | G12: 13188 | H12: 9631 | I12: 12784 | J12: 15546 | K12: 8328 | L12: 11969 | M12: 10561 | N12: 8088 | O12: 9297 | P12: 7433 | Q12: 8773 | R12: 8754 | S12: 10042 | T12: 10593 | U12: 13607 | V12: 14589 | W12: 12043 | X12: 11924 | Y12: 9406 | Z12: 7825 | AC12: =VALUE(TEXT(B12,0)) -> 12100503 | AD12: {=ROUND(AVERAGE(AP12:AR12/25),0)} -> 354 | AE12: {=ROUND(AVERAGE(AM12:AR12/25),0)} -> 434 | AG12: =ROUND(P12*AG$8,0) -> 7433 | AH12: =ROUND(Q12*AH$8,0) -> 8773 | AI12: =ROUND(R12*AI$8,0) -> 8754 | AJ12: =ROUND(S12*AJ$8,0) -> 10042 | AK12: =ROUND(T12*AK$8,0) -> 10593 | AL12: =ROUND(U12*AL$8,0) -> 13607 | AM12: =ROUND(V12*AM$8,0) -> 14589 | AN12: =ROUND(W12*AN$8,0) -> 12043 | ... AQ12: =ROUND(Z12*AQ$8,0) -> 7825 | AR12: =ROUND(O12*AR$8,0) -> 9297
A13: CONDIMENT | B13: 000000000012110202 | C13: HLMNS ΣΑΛΤΣΑ ΚΟΚΤΕΙΛ 3Λ | D13: 115 | E13: 2810 | F13: 1454 | G13: 1678 | H13: 2014 | I13: 1892 | J13: 3054 | K13: 2137 | L13: 1539 | M13: 1489 | N13: 1418 | O13: 1643 | P13: 1631 | Q13: 1307 | R13: 1394 | S13: 305 | T13: 0 | U13: -2 | V13: 0 | X13: 0 | Y13: 0 | AC13: =VALUE(TEXT(B13,0)) -> 12110202 | AD13: {=ROUND(AVERAGE(AP13:AR13/25),0)} -> 22 | AE13: {=ROUND(AVERAGE(AM13:AR13/25),0)} -> 11 | AG13: =ROUND(P13*AG$8,0) -> 1631 | AH13: =ROUND(Q13*AH$8,0) -> 1307 | AI13: =ROUND(R13*AI$8,0) -> 1394 | AJ13: =ROUND(S13*AJ$8,0) -> 305 | AK13: =ROUND(T13*AK$8,0) -> 0 | AL13: =ROUND(U13*AL$8,0) -> -2 | AM13: =ROUND(V13*AM$8,0) -> 0 | AN13: =ROUND(W13*AN$8,0) -> 0 | ... AQ13: =ROUND(Z13*AQ$8,0) -> 0 | AR13: =ROUND(O13*AR$8,0) -> 1643
A14: CONDIMENT | B14: 000000000012110903 | C14: HLMNS ΣΑΛΤΣΑ ΜΟΥΣΤΑΡΔΑΣ 3Λ | D14: 407 | E14: 294 | F14: 476 | G14: 603 | H14: 462 | I14: 510 | J14: 696 | K14: 611 | L14: 361 | M14: 414 | N14: 409 | O14: 542 | P14: 441 | Q14: 403 | R14: 435 | S14: 533 | T14: 470 | U14: 584 | V14: 877 | W14: 397 | X14: 636 | Y14: 463 | Z14: 539 | AC14: =VALUE(TEXT(B14,0)) -> 12110903 | AD14: {=ROUND(AVERAGE(AP14:AR14/25),0)} -> 21 | AE14: {=ROUND(AVERAGE(AM14:AR14/25),0)} -> 23 | AG14: =ROUND(P14*AG$8,0) -> 441 | AH14: =ROUND(Q14*AH$8,0) -> 403 | AI14: =ROUND(R14*AI$8,0) -> 435 | AJ14: =ROUND(S14*AJ$8,0) -> 533 | AK14: =ROUND(T14*AK$8,0) -> 470 | AL14: =ROUND(U14*AL$8,0) -> 584 | AM14: =ROUND(V14*AM$8,0) -> 877 | AN14: =ROUND(W14*AN$8,0) -> 397 | ... AQ14: =ROUND(Z14*AQ$8,0) -> 539 | AR14: =ROUND(O14*AR$8,0) -> 542
A15: CONDIMENT | B15: 000000000012886001 | C15: HLMNS BINΕΓΚΡΕΤ ΒΑΣΙΛΙΚΟΥ FS 6Χ1ΛIT | Q15: -14 | X15: -3 | AC15: =VALUE(TEXT(B15,0)) -> 12886001 | AD15: {=ROUND(AVERAGE(AP15:AR15/25),0)} -> 0 | AE15: {=ROUND(AVERAGE(AM15:AR15/25),0)} -> 0 | AG15: =ROUND(P15*AG$8,0) -> 0 | AH15: =ROUND(Q15*AH$8,0) -> -14 | AI15: =ROUND(R15*AI$8,0) -> 0 | AJ15: =ROUND(S15*AJ$8,0) -> 0 | AK15: =ROUND(T15*AK$8,0) -> 0 | AL15: =ROUND(U15*AL$8,0) -> 0 | AM15: =ROUND(V15*AM$8,0) -> 0 | AN15: =ROUND(W15*AN$8,0) -> 0 | ... AQ15: =ROUND(Z15*AQ$8,0) -> 0 | AR15: =ROUND(O15*AR$8,0) -> 0
A16: CONDIMENT | B16: 000000000012886101 | C16: HELLMANNS ΒΙΝΕΓΚΡΕΤ ΕΣΠΕΡΙΔΟΕΙΔΗ 6Χ1ΛIT | D16: 730 | E16: 900.499 | F16: 958.167 | G16: 1384.166 | H16: 1048.5 | I16: 1514 | J16: 1475.333 | K16: 1110 | L16: 1106.166 | M16: 881 | N16: 796.333 | O16: 849 | P16: 839.833 | Q16: 775.833 | R16: 761 | S16: 1400.833 | T16: 1256.333 | U16: 1526 | V16: 1556.167 | W16: 1088 | X16: 961.833 | Y16: 1169.834 | Z16: 740.666 | AC16: =VALUE(TEXT(B16,0)) -> 12886101 | AD16: {=ROUND(AVERAGE(AP16:AR16/25),0)} -> 37 | AE16: {=ROUND(AVERAGE(AM16:AR16/25),0)} -> 42 | AG16: =ROUND(P16*AG$8,0) -> 840 | AH16: =ROUND(Q16*AH$8,0) -> 776 | AI16: =ROUND(R16*AI$8,0) -> 761 | AJ16: =ROUND(S16*AJ$8,0) -> 1401 | AK16: =ROUND(T16*AK$8,0) -> 1256 | AL16: =ROUND(U16*AL$8,0) -> 1526 | AM16: =ROUND(V16*AM$8,0) -> 1556 | AN16: =ROUND(W16*AN$8,0) -> 1088 | ... AQ16: =ROUND(Z16*AQ$8,0) -> 741 | AR16: =ROUND(O16*AR$8,0) -> 849
A17: CONDIMENT | B17: 000000000013217307 | C17: HELLMANNS ΑΝΑΠΛΗΡΩΜΑ ΜΑΓΙΟΝΕΖΑΣ 1Χ5Λ | E17: -113 | J17: -3 | L17: -6 | M17: 0 | O17: 0 | T17: -1 | Y17: -1 | AC17: =VALUE(TEXT(B17,0)) -> 13217307 | AD17: {=ROUND(AVERAGE(AP17:AR17/25),0)} -> 0 | AE17: {=ROUND(AVERAGE(AM17:AR17/25),0)} -> 0 | AG17: =ROUND(P17*AG$8,0) -> 0 | AH17: =ROUND(Q17*AH$8,0) -> 0 | AI17: =ROUND(R17*AI$8,0) -> 0 | AJ17: =ROUND(S17*AJ$8,0) -> 0 | AK17: =ROUND(T17*AK$8,0) -> -1 | AL17: =ROUND(U17*AL$8,0) -> 0 | AM17: =ROUND(V17*AM$8,0) -> 0 | AN17: =ROUND(W17*AN$8,0) -> 0 | ... AQ17: =ROUND(Z17*AQ$8,0) -> 0 | AR17: =ROUND(O17*AR$8,0) -> 0
A18: CONDIMENT | B18: 000000000015653102 | C18: MAILLE WHOLEGRAIN ΜΟΥΣΤΑΡΔΑ 6X210ΓΡ | D18: 10 | E18: 11 | F18: 32 | G18: 22 | H18: 34 | I18: 3 | J18: 10 | K18: 7 | L18: 12 | M18: 7 | N18: 8 | O18: 8 | P18: 15 | Q18: 8 | R18: 23 | S18: 17 | T18: 28 | U18: 20 | V18: 5 | W18: 14 | X18: 13 | Y18: 18 | Z18: 4 | AC18: =VALUE(TEXT(B18,0)) -> 15653102 | AD18: {=ROUND(AVERAGE(AP18:AR18/25),0)} -> 0 | AE18: {=ROUND(AVERAGE(AM18:AR18/25),0)} -> 0 | AG18: =ROUND(P18*AG$8,0) -> 15 | AH18: =ROUND(Q18*AH$8,0) -> 8 | AI18: =ROUND(R18*AI$8,0) -> 23 | AJ18: =ROUND(S18*AJ$8,0) -> 17 | AK18: =ROUND(T18*AK$8,0) -> 28 | AL18: =ROUND(U18*AL$8,0) -> 20 | AM18: =ROUND(V18*AM$8,0) -> 5 | AN18: =ROUND(W18*AN$8,0) -> 14 | ... AQ18: =ROUND(Z18*AQ$8,0) -> 4 | AR18: =ROUND(O18*AR$8,0) -> 8
A19: CONDIMENT | B19: 000000000015655003 | C19: MAILLE ΜΟΥΣΤΑΡΔΑ DIJON ORIGINALE 6X215 Γ | E19: 5 | F19: 43 | G19: 12 | H19: 28 | I19: 2 | J19: 6 | K19: 12 | L19: 9 | R19: 7 | S19: 7 | T19: 19 | U19: 2 | AC19: =VALUE(TEXT(B19,0)) -> 15655003 | AD19: {=ROUND(AVERAGE(AP19:AR19/25),0)} -> 0 | AE19: {=ROUND(AVERAGE(AM19:AR19/25),0)} -> 0 | AG19: =ROUND(P19*AG$8,0) -> 0 | AH19: =ROUND(Q19*AH$8,0) -> 0 | AI19: =ROUND(R19*AI$8,0) -> 7 | AJ19: =ROUND(S19*AJ$8,0) -> 7 | AK19: =ROUND(T19*AK$8,0) -> 19 | AL19: =ROUND(U19*AL$8,0) -> 2 | AM19: =ROUND(V19*AM$8,0) -> 0 | AN19: =ROUND(W19*AN$8,0) -> 0 | ... AQ19: =ROUND(Z19*AQ$8,0) -> 0 | AR19: =ROUND(O19*AR$8,0) -> 0
A20: CONDIMENT | B20: 000000000015940702 | C20: HLMNS ΑΠΑΛΗ ΜΟΥΣΤΑΡΔΑ 4,8ΚΙΛ | D20: 5270 | E20: 5074 | F20: 5247 | G20: 7861 | H20: 7197 | I20: 6471 | J20: 4380 | L20: 0 | M20: 0 | O20: 0 | AC20: =VALUE(TEXT(B20,0)) -> 15940702 | AD20: {=ROUND(AVERAGE(AP20:AR20/25),0)} -> 0 | AE20: {=ROUND(AVERAGE(AM20:AR20/25),0)} -> 0 | AG20: =ROUND(P20*AG$8,0) -> 0 | AH20: =ROUND(Q20*AH$8,0) -> 0 | AI20: =ROUND(R20*AI$8,0) -> 0 | AJ20: =ROUND(S20*AJ$8,0) -> 0 | AK20: =ROUND(T20*AK$8,0) -> 0 | AL20: =ROUND(U20*AL$8,0) -> 0 | AM20: =ROUND(V20*AM$8,0) -> 0 | AN20: =ROUND(W20*AN$8,0) -> 0 | ... AQ20: =ROUND(Z20*AQ$8,0) -> 0 | AR20: =ROUND(O20*AR$8,0) -> 0
A21: CONDIMENT | B21: 000000000016151003 | C21: HELLMANN'S ΜΑΓΙΟΝΕΖΑ LIGHT 12X450ML | X21: 2 | AC21: =VALUE(TEXT(B21,0)) -> 16151003 | AD21: {=ROUND(AVERAGE(AP21:AR21/25),0)} -> 0 | AE21: {=ROUND(AVERAGE(AM21:AR21/25),0)} -> 0 | AG21: =ROUND(P21*AG$8,0) -> 0 | AH21: =ROUND(Q21*AH$8,0) -> 0 | AI21: =ROUND(R21*AI$8,0) -> 0 | AJ21: =ROUND(S21*AJ$8,0) -> 0 | AK21: =ROUND(T21*AK$8,0) -> 0 | AL21: =ROUND(U21*AL$8,0) -> 0 | AM21: =ROUND(V21*AM$8,0) -> 0 | AN21: =ROUND(W21*AN$8,0) -> 0 | ... AQ21: =ROUND(Z21*AQ$8,0) -> 0 | AR21: =ROUND(O21*AR$8,0) -> 0
A22: CONDIMENT | B22: 000000000017052404 | C22: HELLMANN'S ΝΤΡΕΣΙΝΓΚ BΑΛΣΑΜΙΚΟ 6Χ1Λ | E22: -0.167 | F22: -0.333 | G22: -7.333 | H22: -5 | I22: -4 | J22: -8.334 | K22: -2 | L22: -20 | M22: -14.667 | N22: -1.333 | O22: -6.166 | P22: -9.668 | Q22: -4.333 | R22: -0.334 | S22: -28.167 | T22: -28.501 | U22: -2.667 | V22: -15.5 | W22: -14.001 | X22: -7.833 | Y22: -0.5 | Z22: -1.334 | AC22: =VALUE(TEXT(B22,0)) -> 17052404 | AD22: {=ROUND(AVERAGE(AP22:AR22/25),0)} -> 0 | AE22: {=ROUND(AVERAGE(AM22:AR22/25),0)} -> 0 | AG22: =ROUND(P22*AG$8,0) -> -10 | AH22: =ROUND(Q22*AH$8,0) -> -4 | AI22: =ROUND(R22*AI$8,0) -> 0 | AJ22: =ROUND(S22*AJ$8,0) -> -28 | AK22: =ROUND(T22*AK$8,0) -> -29 | AL22: =ROUND(U22*AL$8,0) -> -3 | AM22: =ROUND(V22*AM$8,0) -> -16 | AN22: =ROUND(W22*AN$8,0) -> -14 | ... AQ22: =ROUND(Z22*AQ$8,0) -> -1 | AR22: =ROUND(O22*AR$8,0) -> -6
A23: CONDIMENT | B23: 000000000017160703 | C23: HELLMAN'S ΜΑΓΙΟΝΕΖΑ 6Χ2 ΛΙΤΡΑ | D23: 0 | E23: -1.666 | F23: -1 | G23: -1.334 | H23: -1.833 | I23: -0.334 | J23: -0.501 | K23: -0.667 | L23: -2.166 | M23: -1.168 | N23: -1.667 | O23: -1 | P23: -1.001 | Q23: -5.334 | R23: -1.5 | S23: -1.166 | T23: -1.167 | U23: -0.333 | V23: -1.334 | W23: -1.332 | X23: -1.667 | Y23: -0.167 | Z23: -1.168 | AC23: =VALUE(TEXT(B23,0)) -> 17160703 | AD23: {=ROUND(AVERAGE(AP23:AR23/25),0)} -> 0 | AE23: {=ROUND(AVERAGE(AM23:AR23/25),0)} -> 0 | AG23: =ROUND(P23*AG$8,0) -> -1 | AH23: =ROUND(Q23*AH$8,0) -> -5 | AI23: =ROUND(R23*AI$8,0) -> -2 | AJ23: =ROUND(S23*AJ$8,0) -> -1 | AK23: =ROUND(T23*AK$8,0) -> -1 | AL23: =ROUND(U23*AL$8,0) -> 0 | AM23: =ROUND(V23*AM$8,0) -> -1 | AN23: =ROUND(W23*AN$8,0) -> -1 | ... AQ23: =ROUND(Z23*AQ$8,0) -> -1 | AR23: =ROUND(O23*AR$8,0) -> -1
A24: CONDIMENT | B24: 000000000017338101 | C24: HELLMANN’S REAL ΜΑΓΙΟΝΕΖΑ 12Χ650 ML | D24: 5 | E24: 5 | AC24: =VALUE(TEXT(B24,0)) -> 17338101 | AD24: {=ROUND(AVERAGE(AP24:AR24/25),0)} -> 0 | AE24: {=ROUND(AVERAGE(AM24:AR24/25),0)} -> 0 | AG24: =ROUND(P24*AG$8,0) -> 0 | AH24: =ROUND(Q24*AH$8,0) -> 0 | AI24: =ROUND(R24*AI$8,0) -> 0 | AJ24: =ROUND(S24*AJ$8,0) -> 0 | AK24: =ROUND(T24*AK$8,0) -> 0 | AL24: =ROUND(U24*AL$8,0) -> 0 | AM24: =ROUND(V24*AM$8,0) -> 0 | AN24: =ROUND(W24*AN$8,0) -> 0 | ... AQ24: =ROUND(Z24*AQ$8,0) -> 0 | AR24: =ROUND(O24*AR$8,0) -> 0
A25: CONDIMENT | B25: 000000000018900805 | C25: HELLMANN'S 1000 ΝΗΣΙΑ DRESSING 4X3LT | D25: -0.25 | E25: -8.25 | F25: -0.5 | G25: -2.75 | H25: -5.25 | I25: -5.75 | J25: -4 | L25: -0.5 | M25: 0 | O25: 0 | Q25: -1 | S25: 0 | T25: -0.25 | V25: 0 | AC25: =VALUE(TEXT(B25,0)) -> 18900805 | AD25: {=ROUND(AVERAGE(AP25:AR25/25),0)} -> 0 | AE25: {=ROUND(AVERAGE(AM25:AR25/25),0)} -> 0 | AG25: =ROUND(P25*AG$8,0) -> 0 | AH25: =ROUND(Q25*AH$8,0) -> -1 | AI25: =ROUND(R25*AI$8,0) -> 0 | AJ25: =ROUND(S25*AJ$8,0) -> 0 | AK25: =ROUND(T25*AK$8,0) -> 0 | AL25: =ROUND(U25*AL$8,0) -> 0 | AM25: =ROUND(V25*AM$8,0) -> 0 | AN25: =ROUND(W25*AN$8,0) -> 0 | ... AQ25: =ROUND(Z25*AQ$8,0) -> 0 | AR25: =ROUND(O25*AR$8,0) -> 0
A26: CONDIMENT | B26: 000000000019485901 | C26: HELLMANN’S ΜΟΥΣΤΑΡΔΑ ΜΙΝΙ ΒΑΖ. 1X80X33ML | D26: 15 | E26: 37 | F26: 73 | G26: 170 | H26: 332 | I26: 126 | J26: 198 | K26: 153 | L26: 70 | M26: 37 | N26: 2 | O26: 3 | P26: 7 | Q26: 29 | R26: 73 | X26: 0 | AC26: =VALUE(TEXT(B26,0)) -> 19485901 | AD26: {=ROUND(AVERAGE(AP26:AR26/25),0)} -> 0 | AE26: {=ROUND(AVERAGE(AM26:AR26/25),0)} -> 0 | AG26: =ROUND(P26*AG$8,0) -> 7 | AH26: =ROUND(Q26*AH$8,0) -> 29 | AI26: =ROUND(R26*AI$8,0) -> 73 | AJ26: =ROUND(S26*AJ$8,0) -> 0 | AK26: =ROUND(T26*AK$8,0) -> 0 | AL26: =ROUND(U26*AL$8,0) -> 0 | AM26: =ROUND(V26*AM$8,0) -> 0 | AN26: =ROUND(W26*AN$8,0) -> 0 | ... AQ26: =ROUND(Z26*AQ$8,0) -> 0 | AR26: =ROUND(O26*AR$8,0) -> 3
A27: CONDIMENT | B27: 000000000019486001 | C27: HELLMANN’S ΚΕΤΣΑΠ MINI ΒΑΖ. 1X80X33ML | E27: 93 | F27: 166 | G27: 416 | H27: 566 | I27: 362 | J27: 806 | K27: 487 | L27: 243 | M27: 102 | N27: 14 | O27: 31 | P27: 14 | Q27: 85 | R27: 18 | X27: 0 | AC27: =VALUE(TEXT(B27,0)) -> 19486001 | AD27: {=ROUND(AVERAGE(AP27:AR27/25),0)} -> 0 | AE27: {=ROUND(AVERAGE(AM27:AR27/25),0)} -> 0 | AG27: =ROUND(P27*AG$8,0) -> 14 | AH27: =ROUND(Q27*AH$8,0) -> 85 | AI27: =ROUND(R27*AI$8,0) -> 18 | AJ27: =ROUND(S27*AJ$8,0) -> 0 | AK27: =ROUND(T27*AK$8,0) -> 0 | AL27: =ROUND(U27*AL$8,0) -> 0 | AM27: =ROUND(V27*AM$8,0) -> 0 | AN27: =ROUND(W27*AN$8,0) -> 0 | ... AQ27: =ROUND(Z27*AQ$8,0) -> 0 | AR27: =ROUND(O27*AR$8,0) -> 31
A28: CONDIMENT | B28: 000000000019854501 | C28: HELLMANN'S ΜΟΥΣΤAΡΔΑ ΑΠΑΛΗ ΤΟΠΝΤ 12Χ265Γ | G28: 5 | J28: 4 | L28: 1 | Q28: 20 | AC28: =VALUE(TEXT(B28,0)) -> 19854501 | AD28: {=ROUND(AVERAGE(AP28:AR28/25),0)} -> 0 | AE28: {=ROUND(AVERAGE(AM28:AR28/25),0)} -> 0 | AG28: =ROUND(P28*AG$8,0) -> 0 | AH28: =ROUND(Q28*AH$8,0) -> 20 | AI28: =ROUND(R28*AI$8,0) -> 0 | AJ28: =ROUND(S28*AJ$8,0) -> 0 | AK28: =ROUND(T28*AK$8,0) -> 0 | AL28: =ROUND(U28*AL$8,0) -> 0 | AM28: =ROUND(V28*AM$8,0) -> 0 | AN28: =ROUND(W28*AN$8,0) -> 0 | ... AQ28: =ROUND(Z28*AQ$8,0) -> 0 | AR28: =ROUND(O28*AR$8,0) -> 0
A29: CONDIMENT | B29: 64773377 | C29: HLMNS ΜΑΓΙΟΝΕΖΑ REAL 5Λ | D29: 11910 | E29: 10133 | F29: 13605 | G29: 20431 | H29: 16561 | I29: 14058 | J29: -2 | L29: -1 | M29: 0 | O29: 0 | AC29: =VALUE(TEXT(B29,0)) -> 64773377 | AD29: {=ROUND(AVERAGE(AP29:AR29/25),0)} -> 0 | AE29: {=ROUND(AVERAGE(AM29:AR29/25),0)} -> 0 | AG29: =ROUND(P29*AG$8,0) -> 0 | AH29: =ROUND(Q29*AH$8,0) -> 0 | AI29: =ROUND(R29*AI$8,0) -> 0 | AJ29: =ROUND(S29*AJ$8,0) -> 0 | AK29: =ROUND(T29*AK$8,0) -> 0 | AL29: =ROUND(U29*AL$8,0) -> 0 | AM29: =ROUND(V29*AM$8,0) -> 0 | AN29: =ROUND(W29*AN$8,0) -> 0 | ... AQ29: =ROUND(Z29*AQ$8,0) -> 0 | AR29: =ROUND(O29*AR$8,0) -> 0
A30: CONDIMENT | B30: 000000000022110402 | C30: HLMNS ΣΑΛΤΣΑ ΜΕ ΓΕΥΣΗ ΓΙΑΟΥΡΤΙΟΥ 3Λ | E30: -9 | I30: 0 | L30: 0 | M30: 0 | O30: 0 | AC30: =VALUE(TEXT(B30,0)) -> 22110402 | AD30: {=ROUND(AVERAGE(AP30:AR30/25),0)} -> 0 | AE30: {=ROUND(AVERAGE(AM30:AR30/25),0)} -> 0 | AG30: =ROUND(P30*AG$8,0) -> 0 | AH30: =ROUND(Q30*AH$8,0) -> 0 | AI30: =ROUND(R30*AI$8,0) -> 0 | AJ30: =ROUND(S30*AJ$8,0) -> 0 | AK30: =ROUND(T30*AK$8,0) -> 0 | AL30: =ROUND(U30*AL$8,0) -> 0 | AM30: =ROUND(V30*AM$8,0) -> 0 | AN30: =ROUND(W30*AN$8,0) -> 0 | ... AQ30: =ROUND(Z30*AQ$8,0) -> 0 | AR30: =ROUND(O30*AR$8,0) -> 0
A31: CONDIMENT | B31: 000000000028000701 | C31: HELLMANN'S ΣΙΖΑΡΣ DRESSING 3X3 lt. | D31: 4397.667 | E31: 4342.001 | F31: 4665.333 | G31: 4640.334 | H31: 8748.667 | I31: 8076.668 | J31: 8172.333 | K31: 6551.334 | L31: 5030.334 | M31: 5121 | N31: 4063.334 | O31: 4105.667 | P31: 4325 | Q31: 3743.333 | R31: 5181.334 | S31: 5582.333 | T31: 6417.334 | U31: 8078.333 | V31: 9901.667 | W31: 7329.001 | X31: 5118 | Y31: 4479 | Z31: 4129.667 | AC31: =VALUE(TEXT(B31,0)) -> 28000701 | AD31: {=ROUND(AVERAGE(AP31:AR31/25),0)} -> 170 | AE31: {=ROUND(AVERAGE(AM31:AR31/25),0)} -> 234 | AG31: =ROUND(P31*AG$8,0) -> 4325 | AH31: =ROUND(Q31*AH$8,0) -> 3743 | AI31: =ROUND(R31*AI$8,0) -> 5181 | AJ31: =ROUND(S31*AJ$8,0) -> 5582 | AK31: =ROUND(T31*AK$8,0) -> 6417 | AL31: =ROUND(U31*AL$8,0) -> 8078 | AM31: =ROUND(V31*AM$8,0) -> 9902 | AN31: =ROUND(W31*AN$8,0) -> 7329 | ... AQ31: =ROUND(Z31*AQ$8,0) -> 4130 | AR31: =ROUND(O31*AR$8,0) -> 4106
A32: CONDIMENT | B32: 000000000031132401 | C32: HELLMANN'S ΑΠΑΛΗ ΜΟΥΣΤΑΡΔΑ 12X500 ΓΡ | D32: 26 | E32: 23 | F32: 69 | G32: 86 | H32: 2 | I32: 61 | J32: 89 | K32: -21 | L32: 46 | M32: 28 | N32: 21 | O32: 17 | P32: 18 | Q32: 25 | R32: 17 | S32: 74 | T32: 30 | U32: 55 | V32: 40 | W32: 14 | X32: 13 | Y32: 19 | Z32: 18 | AC32: =VALUE(TEXT(B32,0)) -> 31132401 | AD32: {=ROUND(AVERAGE(AP32:AR32/25),0)} -> 1 | AE32: {=ROUND(AVERAGE(AM32:AR32/25),0)} -> 1 | AG32: =ROUND(P32*AG$8,0) -> 18 | AH32: =ROUND(Q32*AH$8,0) -> 25 | AI32: =ROUND(R32*AI$8,0) -> 17 | AJ32: =ROUND(S32*AJ$8,0) -> 74 | AK32: =ROUND(T32*AK$8,0) -> 30 | AL32: =ROUND(U32*AL$8,0) -> 55 | AM32: =ROUND(V32*AM$8,0) -> 40 | AN32: =ROUND(W32*AN$8,0) -> 14 | ... AQ32: =ROUND(Z32*AQ$8,0) -> 18 | AR32: =ROUND(O32*AR$8,0) -> 17
A33: CONDIMENT | B33: 000000000031132501 | C33: HELLMANN'S ΠΙΚΑΝΤΙΚΗ ΜΟΥΣΤΑΡΔ 12Χ250ΓΡ | J33: 1 | AC33: =VALUE(TEXT(B33,0)) -> 31132501 | AD33: {=ROUND(AVERAGE(AP33:AR33/25),0)} -> 0 | AE33: {=ROUND(AVERAGE(AM33:AR33/25),0)} -> 0 | AG33: =ROUND(P33*AG$8,0) -> 0 | AH33: =ROUND(Q33*AH$8,0) -> 0 | AI33: =ROUND(R33*AI$8,0) -> 0 | AJ33: =ROUND(S33*AJ$8,0) -> 0 | AK33: =ROUND(T33*AK$8,0) -> 0 | AL33: =ROUND(U33*AL$8,0) -> 0 | AM33: =ROUND(V33*AM$8,0) -> 0 | AN33: =ROUND(W33*AN$8,0) -> 0 | ... AQ33: =ROUND(Z33*AQ$8,0) -> 0 | AR33: =ROUND(O33*AR$8,0) -> 0
A34: CONDIMENT | B34: 000000000031132601 | C34: HELLMANN'S ΠΙΚΑΝΤΙΚΗ ΜΟΥΣΤΑΡΔ 12Χ500ΓΡ | F34: 4 | M34: 2 | O34: 2 | S34: 2 | X34: 1 | Z34: 2 | AC34: =VALUE(TEXT(B34,0)) -> 31132601 | AD34: {=ROUND(AVERAGE(AP34:AR34/25),0)} -> 0 | AE34: {=ROUND(AVERAGE(AM34:AR34/25),0)} -> 0 | AG34: =ROUND(P34*AG$8,0) -> 0 | AH34: =ROUND(Q34*AH$8,0) -> 0 | AI34: =ROUND(R34*AI$8,0) -> 0 | AJ34: =ROUND(S34*AJ$8,0) -> 2 | AK34: =ROUND(T34*AK$8,0) -> 0 | AL34: =ROUND(U34*AL$8,0) -> 0 | AM34: =ROUND(V34*AM$8,0) -> 0 | AN34: =ROUND(W34*AN$8,0) -> 0 | ... AQ34: =ROUND(Z34*AQ$8,0) -> 2 | AR34: =ROUND(O34*AR$8,0) -> 2
A35: CONDIMENT | B35: 000000000036010201 | C35: HELLMANN'S ΚΕΤΣΑΠ 3Χ4,8 ΚΙΛΑ | D35: 2422 | E35: 1681.001 | F35: 2269 | G35: 3448 | H35: 3126.333 | I35: 3310 | J35: 4178.334 | K35: 3097.333 | L35: 3171.667 | M35: 2300.001 | N35: 1470.667 | O35: 2307 | P35: 1702 | Q35: 2241.667 | R35: 2502.334 | S35: 3100.667 | T35: 3549.001 | U35: 3002 | V35: 212.334 | W35: -0.667 | X35: -0.667 | Y35: -0.999 | AC35: =VALUE(TEXT(B35,0)) -> 36010201 | AD35: {=ROUND(AVERAGE(AP35:AR35/25),0)} -> 31 | AE35: {=ROUND(AVERAGE(AM35:AR35/25),0)} -> 17 | AG35: =ROUND(P35*AG$8,0) -> 1702 | AH35: =ROUND(Q35*AH$8,0) -> 2242 | AI35: =ROUND(R35*AI$8,0) -> 2502 | AJ35: =ROUND(S35*AJ$8,0) -> 3101 | AK35: =ROUND(T35*AK$8,0) -> 3549 | AL35: =ROUND(U35*AL$8,0) -> 3002 | AM35: =ROUND(V35*AM$8,0) -> 212 | AN35: =ROUND(W35*AN$8,0) -> -1 | ... AQ35: =ROUND(Z35*AQ$8,0) -> 0 | AR35: =ROUND(O35*AR$8,0) -> 2307
A36: CONDIMENT | B36: 000000000039495401 | C36: HELLMANN’S ΜΑΓΙΟΝΕΖΑ ΜΙΝΙ ΒΑΖ. 1X80X33ML | D36: 5 | E36: 96 | F36: 318 | G36: 309 | H36: 492 | I36: 357 | J36: 566 | K36: 328 | L36: 143 | M36: 56 | N36: 5 | O36: 34 | P36: 3 | Q36: 90 | R36: 163 | X36: 0 | AC36: =VALUE(TEXT(B36,0)) -> 39495401 | AD36: {=ROUND(AVERAGE(AP36:AR36/25),0)} -> 0 | AE36: {=ROUND(AVERAGE(AM36:AR36/25),0)} -> 0 | AG36: =ROUND(P36*AG$8,0) -> 3 | AH36: =ROUND(Q36*AH$8,0) -> 90 | AI36: =ROUND(R36*AI$8,0) -> 163 | AJ36: =ROUND(S36*AJ$8,0) -> 0 | AK36: =ROUND(T36*AK$8,0) -> 0 | AL36: =ROUND(U36*AL$8,0) -> 0 | AM36: =ROUND(V36*AM$8,0) -> 0 | AN36: =ROUND(W36*AN$8,0) -> 0 | ... AQ36: =ROUND(Z36*AQ$8,0) -> 0 | AR36: =ROUND(O36*AR$8,0) -> 34
A37: CONDIMENT | B37: 000000000046033501 | C37: HELLMANN'S DIJONNAISE 12X240 ΓΡ | E37: 10 | F37: 17 | G37: 6 | H37: 10 | I37: 5 | J37: 26 | K37: 31 | M37: 14 | N37: 14 | O37: 14 | P37: 22 | Q37: 18 | R37: 16 | S37: 26 | T37: 12 | U37: 12 | V37: 25 | W37: 43 | X37: -11 | Y37: 13 | Z37: 13 | AC37: =VALUE(TEXT(B37,0)) -> 46033501 | AD37: {=ROUND(AVERAGE(AP37:AR37/25),0)} -> 1 | AE37: {=ROUND(AVERAGE(AM37:AR37/25),0)} -> 1 | AG37: =ROUND(P37*AG$8,0) -> 22 | AH37: =ROUND(Q37*AH$8,0) -> 18 | AI37: =ROUND(R37*AI$8,0) -> 16 | AJ37: =ROUND(S37*AJ$8,0) -> 26 | AK37: =ROUND(T37*AK$8,0) -> 12 | AL37: =ROUND(U37*AL$8,0) -> 12 | AM37: =ROUND(V37*AM$8,0) -> 25 | AN37: =ROUND(W37*AN$8,0) -> 43 | ... AQ37: =ROUND(Z37*AQ$8,0) -> 13 | AR37: =ROUND(O37*AR$8,0) -> 14
A38: CONDIMENT | B38: 000000000062678655 | C38: HELLMANN’S REAL MAΓΙΟΝΕΖΑ ΤΟΠΝΤΑ 6X750ML | K38: 1 | L38: 1 | AC38: =VALUE(TEXT(B38,0)) -> 62678655 | AD38: {=ROUND(AVERAGE(AP38:AR38/25),0)} -> 0 | AE38: {=ROUND(AVERAGE(AM38:AR38/25),0)} -> 0 | AG38: =ROUND(P38*AG$8,0) -> 0 | AH38: =ROUND(Q38*AH$8,0) -> 0 | AI38: =ROUND(R38*AI$8,0) -> 0 | AJ38: =ROUND(S38*AJ$8,0) -> 0 | AK38: =ROUND(T38*AK$8,0) -> 0 | AL38: =ROUND(U38*AL$8,0) -> 0 | AM38: =ROUND(V38*AM$8,0) -> 0 | AN38: =ROUND(W38*AN$8,0) -> 0 | ... AQ38: =ROUND(Z38*AQ$8,0) -> 0 | AR38: =ROUND(O38*AR$8,0) -> 0
A39: CONDIMENT | B39: 000000000062724322 | C39: HELLMANN'S ΚΕΤΣΑΠ ΚΛΑΣΣΙΚΗ TD 12X550 ΓΡ | H39: 10 | I39: 5 | K39: 5 | P39: 5 | Q39: 51 | S39: 10 | U39: 10 | AC39: =VALUE(TEXT(B39,0)) -> 62724322 | AD39: {=ROUND(AVERAGE(AP39:AR39/25),0)} -> 0 | AE39: {=ROUND(AVERAGE(AM39:AR39/25),0)} -> 0 | AG39: =ROUND(P39*AG$8,0) -> 5 | AH39: =ROUND(Q39*AH$8,0) -> 51 | AI39: =ROUND(R39*AI$8,0) -> 0 | AJ39: =ROUND(S39*AJ$8,0) -> 10 | AK39: =ROUND(T39*AK$8,0) -> 0 | AL39: =ROUND(U39*AL$8,0) -> 10 | AM39: =ROUND(V39*AM$8,0) -> 0 | AN39: =ROUND(W39*AN$8,0) -> 0 | ... AQ39: =ROUND(Z39*AQ$8,0) -> 0 | AR39: =ROUND(O39*AR$8,0) -> 0
A40: CONDIMENT | B40: 000000000062739289 | C40: MAILLE DIJONNAISE 6X185 ΓΡ | K40: 5 | AC40: =VALUE(TEXT(B40,0)) -> 62739289 | AD40: {=ROUND(AVERAGE(AP40:AR40/25),0)} -> 0 | AE40: {=ROUND(AVERAGE(AM40:AR40/25),0)} -> 0 | AG40: =ROUND(P40*AG$8,0) -> 0 | AH40: =ROUND(Q40*AH$8,0) -> 0 | AI40: =ROUND(R40*AI$8,0) -> 0 | AJ40: =ROUND(S40*AJ$8,0) -> 0 | AK40: =ROUND(T40*AK$8,0) -> 0 | AL40: =ROUND(U40*AL$8,0) -> 0 | AM40: =ROUND(V40*AM$8,0) -> 0 | AN40: =ROUND(W40*AN$8,0) -> 0 | ... AQ40: =ROUND(Z40*AQ$8,0) -> 0 | AR40: =ROUND(O40*AR$8,0) -> 0
...

Sheet MRDRS Mapping
A3: Κατηγορία | B3: Trade | C3: MRDR | D3: ΠΕΡΙΓΡΑΦΗ ΠΡΟΪΟΝΤΟΣ | F3: Tot.SL | G3: SL Ind. | H3: Tot.SL | I3: SL Ind. | J3: Κατηγορία
A4: ΖΩΜΟΙ | B4: 22010602 | C4: 22010602 | D4: KNORROX ΖΩΜΟΣ ΚΟΤΑΣ 1x7 ΚΙΛ. | F4: 18 | G4: M | H4: 548 | I4: D | J4: ΖΩΜΟΙ | K4: =VLOOKUP(C4,#REF!,1,0) -> #REF!
A5: ΖΩΜΟΙ | B5: 12011702 | C5: 12011702 | D5: KNORR ΖΩΜΟΣ ΚΟΤΑΣ 1*4Κ | F5: 18 | G5: M | H5: 548 | I5: D | J5: ΖΩΜΟΙ | K5: =VLOOKUP(C5,#REF!,1,0) -> #REF!
A6: ΖΩΜΟΙ | B6: 39631001 | C6: 39631001 | D6: KNORR ΖΩΜΟΣ ΚΟΤΑΣ 6*1,2Κ | F6: 18 | G6: M | H6: 548 | I6: D | J6: ΖΩΜΟΙ | K6: =VLOOKUP(C6,#REF!,1,0) -> #REF!
A7: ΖΩΜΟΙ | B7: 19522701 | C7: 19522701 | D7: KN ΕΠΑΓΓΕΛΜΑΤΙΚΟΣ ΖΩΜΟΣ ΚΟΤΟΠΟΥΛΟ2X800ΓΡ | F7: 12 | G7: M | H7: 365 | I7: D | J7: ΖΩΜΟΙ | K7: =VLOOKUP(C7,#REF!,1,0) -> #REF!
A8: ΖΩΜΟΙ | B8: 29256601 | C8: 29256601 | D8: KNORR ΖΩΜΟΣ ΚΟΤΑΣ ΣΕ ΚΟΚΚΟΥΣ 6Χ1 ΚΙΛ | F8: 15 | G8: M | H8: 456 | I8: D | J8: ΖΩΜΟΙ
A9: ΖΩΜΟΙ | B9: 68764357 | C9: 68764357 | D9: KN ΖΩΜΟΣ ΒΟΔΙΝΟΥ 1x7 ΚΙΛ. | F9: 18 | G9: M | H9: 548 | I9: D | J9: ΖΩΜΟΙ | K9: =VLOOKUP(C9,#REF!,1,0) -> #REF!
A10: ΖΩΜΟΙ | B10: 12011802 | C10: 12011802 | D10: KNORR ΖΩΜΟΣ ΒΟΔΙΝΟΥ 1X4 ΚΙΛ. | F10: 18 | G10: M | H10: 548 | I10: D | J10: ΖΩΜΟΙ | K10: =VLOOKUP(C10,#REF!,1,0) -> #REF!
A11: ΖΩΜΟΙ | B11: 19630701 | C11: 19630701 | D11: KNORR ΖΩΜΟΣ ΒΟΔΙΝΟΥ 6x1,2ΚΙΛ | F11: 18 | G11: M | H11: 548 | I11: D | J11: ΖΩΜΟΙ | K11: =VLOOKUP(C11,#REF!,1,0) -> #REF!
A12: ΖΩΜΟΙ | B12: 19502801 | C12: 68448698 | D12: KN ΕΠΑΓΓΕΛΜΑΤΙΚΟΣ ΖΩΜΟΣ ΒΟΔΙΝΟΥ 2X800G | F12: 12 | G12: M | H12: 365 | I12: D | J12: ΖΩΜΟΙ | K12: =VLOOKUP(C12,#REF!,1,0) -> #REF!
A13: ΖΩΜΟΙ | B13: 22011902 | C13: 68760225 | D13: KNORR ΖΩΜΟΣ ΛΑΧΑΝΙΚΩΝ 1Χ4Κ | F13: 18 | G13: M | H13: 548 | I13: D | J13: ΖΩΜΟΙ | K13: =VLOOKUP(C13,#REF!,1,0) -> #REF!
A14: ΖΩΜΟΙ | B14: 68770074 | C14: 68770074 | D14: KNORR ΖΩΜOΣ ΛΑΧΑΝΙΚΩΝ 6Χ1,5 ΚΙΛ | F14: 18 | G14: M | H14: 548 | I14: D | J14: ΖΩΜΟΙ | K14: =VLOOKUP(C14,#REF!,1,0) -> #REF!
A15: ΖΩΜΟΙ | B15: 68768919 | C15: 68768919 | D15: KNORR ΖΩΜΟΣ ΛΑΧΑΝ ΣΕ ΣΚΟΝΗ 6Χ1,25 ΚΙΛ | F15: 18 | G15: M | H15: 548 | I15: D | J15: ΖΩΜΟΙ | K15: =VLOOKUP(C15,#REF!,1,0) -> #REF!
A16: ΖΩΜΟΙ | B16: 19503901 | C16: 68448709 | D16: KN ΕΠΑΓΓΕΛΜΑΤΙΚΟΣ ΖΩΜΟΣ ΛΑΧΑΝΙΚΩΝ 2X800ΓΡ | F16: 12 | G16: M | H16: 365 | I16: D | J16: ΖΩΜΟΙ | K16: =VLOOKUP(C16,#REF!,1,0) -> #REF!
A17: ΖΩΜΟΙ | B17: 11336407 | C17: 68729734 | D17: KNORR ΖΩΜΟΣ ΣΑΦΡΑΝ 2Χ0,8 ΚΙΛ. | F17: 18 | G17: M | H17: 548 | I17: D | J17: ΖΩΜΟΙ | K17: =VLOOKUP(C17,#REF!,1,0) -> #REF!
A18: ΖΩΜΟΙ | B18: 17253001 | C18: 17253003 | D18: KNORR ΖΩΜΟΣ ΨΑΡΙΟΥ 3X1 KIΛΟ | F18: 18 | G18: M | H18: 548 | I18: D | J18: ΖΩΜΟΙ | K18: =VLOOKUP(C18,#REF!,1,0) -> #REF!
A19: ΖΩΜΟΙ | B19: 29603001 | C19: 29603001 | D19: ΚΝORR ΥΓΡΟΣ ΖΩΜΟΣ ΟΣΤΡΑΚΟΕΙΔΩΝ 6Χ1L | F19: 12 | G19: M | H19: 365 | I19: D | J19: ΖΩΜΟΙ | K19: =VLOOKUP(C19,#REF!,1,0) -> #REF!
A20: ΖΩΜΟΙ | B20: 67251853 | C20: 67251853 | D20: KNORR ΥΓΡΟΣ ΖΩΜΟΣ ΚΟΤΟΠΟΥΛΟΥ 8X1L | F20: 12 | G20: M | H20: 365 | I20: D | J20: ΖΩΜΟΙ
A21: ΖΩΜΟΙ | B21: 67251848 | C21: 67251848 | D21: KNORR ΥΓΡΟΣ ΖΩΜΟΣ ΜΟΣΧΑΡΙ 8X1L | F21: 12 | G21: M | H21: 365 | I21: D | J21: ΖΩΜΟΙ
A22: ΖΩΜΟΙ | B22: 18928001 | C22: 68660152 | D22: KNORR 123 ΖΩΜΟΣ ΜΕ ΓΕΥΣΗ ΚΟΤΑ 1Χ3,5KG | F22: 15 | G22: M | H22: 456 | I22: D | J22: ΖΩΜΟΙ | K22: =VLOOKUP(C22,#REF!,1,0) -> #REF!
A23: ΖΩΜΟΙ | B23: 10003604 | C23: 68731560 | D23: KNORR ΖΩΜΟΣ ΜΑΝΙΤΑΡΙ ΜΕ PORCINI 6X0,5 ΚΙΛ | F23: 18 | G23: M | H23: 548 | I23: D | J23: ΖΩΜΟΙ | K23: =VLOOKUP(C23,#REF!,1,0) -> #REF!
A24: ΖΩΜΟΙ | B24: 68755990 | C24: 68755990 | D24: ΚΝ ΖΩΜΟΣ ΚΟΤΑΣ ΣΕ ΣΚΟΝΗ 6Χ1 ΚΙΛ. | F24: 15 | G24: M | H24: 456 | I24: D | J24: ΖΩΜΟΙ | K24: =VLOOKUP(C24,#REF!,1,0) -> #REF!
A25: ΖΩΜΟΙ | B25: 68768919 | C25: 68768919 | D25: KNORR ΖΩΜΟΣ ΛΑΧΑΝ ΣΕ ΣΚΟΝΗ 6Χ1,25 ΚΙΛ | F25: 18 | G25: M | H25: 548 | I25: D | J25: ΖΩΜΟΙ | K25: =VLOOKUP(C25,#REF!,1,0) -> #REF!
A26: ΖΩΜΟΙ | B26: 68703091 | C26: 68703091 | D26: KN ΖΩΜΟΣ ΓΕΥΣΗ ΒΟΔΙΝΟΥ ΣΕ ΣΚΟΝΗ1Χ3,5 ΚΙΛ | F26: 18 | G26: M | H26: 548 | I26: D | J26: ΖΩΜΟΙ | K26: =VLOOKUP(C26,#REF!,1,0) -> #REF!
A27: ΖΩΜΟΙ | B27: 68703091 | C27: 68703091 | D27: KN ΖΩΜΟΣ ΓΕΥΣΗ ΒΟΔΙΝΟΥ ΣΕ ΣΚΟΝΗ1Χ3,5 ΚΙΛ | F27: 18 | G27: M | H27: 548 | I27: D | J27: ΖΩΜΟΙ | K27: =VLOOKUP(C27,#REF!,1,0) -> #REF!
A28: ΖΩΜΟΙ | B28: 68660152 | C28: 68660152 | D28: KN ΖΩΜΟΣ ΓΕΥΣΗ ΚΟΤΑ ΣΕ ΣΚΟΝΗ 1X3,5 KΙΛ | F28: 15 | G28: M | H28: 456 | I28: D | J28: ΖΩΜΟΙ | K28: =VLOOKUP(C28,#REF!,1,0) -> #REF!
A29: SEASONINGS | B29: T20310 | C29: 68448695 | D29: KNORR PRIMERBA ΜΠΟΥΚΕΤΟ ΜΥΡΩΔΙΚΩΝ ΤΟΥ ΑΓΡΟΥ 2 x 340ΓΡ. | F29: 365 | G29: D | H29: 365 | I29: D | J29: SEASONINGS | K29: =VLOOKUP(C29,#REF!,1,0) -> #REF!
A30: SEASONINGS | B30: T20325 | C30: 17193301 | D30: KNORR PRIMERBA ΠΑΣΤΑ ΘΥΜΑΡΙ 2×340 ΓΡ. | F30: 365 | G30: D | H30: 365 | I30: D | J30: SEASONINGS | K30: =VLOOKUP(C30,#REF!,1,0) -> #REF!
A31: SEASONINGS | B31: 64303966 | C31: 64303966 | D31: KNORR PRIMERBA ΠΕΣΤΟ ΜΕ ΚΟΥΚΟΥΝΑΡΙ 2×340ΓΡ. | F31: 365 | G31: D | H31: 365 | I31: D | J31: SEASONINGS | K31: =VLOOKUP(C31,#REF!,1,0) -> #REF!
A32: SEASONINGS | B32: T20324 | C32: 17193401 | D32: KNORR PRIMERBA ΠΑΣΤΑ ΒΑΣΙΛΙΚΟΥ 2×340 ΓΡ. | F32: 365 | G32: D | H32: 365 | I32: D | J32: SEASONINGS | K32: =VLOOKUP(C32,#REF!,1,0) -> #REF!
A33: SEASONINGS | B33: 67463898 | C33: 64303850 | D33: KNORR PRIMERBA ΠΑΣΤΑ ΜΑΝΙΤΑΡΙ 2Χ340 ΓΡ | F33: 365 | G33: D | H33: 366 | I33: D | J33: SEASONINGS | K33: =VLOOKUP(C33,#REF!,1,0) -> #REF!
A34: SEASONINGS | B34: T20327 | C34: 17193101 | D34: KNORR PRIMERBA ΠΑΣΤΑ ΔΕΝΔΡΟΛΙΒΑΝΟ 2×340ΓΡ. | F34: 365 | G34: D | H34: 365 | I34: D | J34: SEASONINGS | K34: =VLOOKUP(C34,#REF!,1,0) -> #REF!
A35: SEASONINGS | B35: 13072002 | C35: 13072002 | D35: KNORR PRIMERBA ΠΑΣΤΑ ΑΝΗΘΟΣ 2×340 ΓΡ. | F35: 365 | G35: D | H35: 365 | I35: D | J35: SEASONINGS
A36: SEASONINGS | B36: T20326 | C36: 17193201 | D36: KNORR PRIMERBA ΠΑΣΤΑ ΣΚΟΡΔΟ 2×340 ΓΡ. | F36: 365 | G36: D | H36: 365 | I36: D | J36: SEASONINGS | K36: =VLOOKUP(C36,#REF!,1,0) -> #REF!
A37: SEASONINGS | B37: 68706527 | C37: 68706527 | D37: KNORR PRIMERBA PESTO ROSSO ΜΕ ΤΟΜΑΤΑ & ΒΑΣΙΛΙΚΟ 2X340gr | F37: 365 | G37: D | H37: 365 | I37: D | J37: SEASONINGS | K37: =VLOOKUP(C37,#REF!,1,0) -> #REF!
A38: SEASONINGS | B38: T20329 | C38: 81334801 | D38: KNORR PRIMERBA ΨΗΜΕΝΟ ΚΡΕΜΜΥΔΙ 2Χ340 ΓΡ. | F38: 365 | G38: D | H38: 365 | I38: D | J38: SEASONINGS | K38: =VLOOKUP(C38,#REF!,1,0) -> #REF!
A39: SEASONINGS | B39: 19513602 | C39: 19513602 | D39: KNORR ΑΡΩΜΑΤ 6X500ΓΡ | F39: 18 | G39: M | H39: 548 | I39: D | J39: SEASONINGS | K39: =VLOOKUP(C39,#REF!,1,0) -> #REF!
A40: ΣΑΛΤΣΕΣ | B40: 16869301 | C40: 16869301 | D40: KNORR ΣΑΛΤΣΑ ΚΑΡΡΥ 6Χ1400ΓΡ | F40: 18 | G40: M | H40: 548 | I40: D | J40: ΣΑΛΤΣΕΣ | K40: =VLOOKUP(C40,#REF!,1,0) -> #REF!
A41: ΣΑΛΤΣΕΣ | B41: 6404803 | C41: 64882125 | D41: KNORR ΣΑΛΤΣΑ ΗOLLANDAISE 6X825ΓΡ | F41: 12 | G41: M | H41: 365 | I41: D | J41: ΣΑΛΤΣΕΣ | K41: =VLOOKUP(C41,#REF!,1,0) -> #REF!
A42: ΣΑΛΤΣΕΣ | B42: 16866501 | C42: 16866501 | D42: KNORR ΣΑΛΤΣΑ ΜΠΕΑΡΝΑΙΖ 6Χ900 ΓΡ | F42: 12 | G42: M | H42: 365 | I42: D | J42: ΣΑΛΤΣΕΣ | K42: =VLOOKUP(C42,#REF!,1,0) -> #REF!
...

Sheet ObsRiskPerMonth
A1: Sum of Cost of Risk (standard price) | B1: Column Labels
B2: 2021 | C2: 2022 | D2: 2023 | J2: 2023 Total | K2: 2024 | M2: 2024 Total | N2: Grand Total
A3: Row Labels | D3: Ιαν | E3: Φεβ | F3: Μαρ | G3: Απρ | H3: Μαϊ | I3: Ιουν | K3: Ιαν | L3: Φεβ
A4: ΖΩΜΟΙ | B4: 77.544 | C4: 17485.864 | N4: 17563.408
A5: SEASONINGS | C5: 1771.3642 | N5: 1771.3642
A6: ΣΑΛΤΣΕΣ | C6: 12350.845 | N6: 12350.845
A7: ΥΓΡΕΣ ΣΑΛΤΣΕΣ | B7: 854.87711 | C7: 1755.5681 | D7: 55.2735 | J7: 55.2735 | N7: 2665.7187
A8: ΣΟΥΠΕΣ | B8: 15.48 | C8: 1163.6847 | D8: 1377.5024 | F8: 347.476 | G8: 762.45608 | J8: 2487.4345 | N8: 3666.5993
A9: WORLD CUISINES | C9: 21.33 | N9: 21.33
A10: ΜΑΓΙΟΝΕΖΑ | B10: 2238.5068 | C10: 729.52764 | N10: 2968.0344
A11: ΚΕΤΣΑΠ | C11: 636.37087 | N11: 636.37087
A12: ΜΟΥΣΤΑΡΔΑ | C12: 307.98877 | N12: 307.98877
A13: DRESSINGS | B13: 3855.6627 | C13: 0 | N13: 3855.6627
A14: ΣΑΛΤΣΕΣ ΣΑΝΤΟΥΪΤΣ | C14: 911.50222 | N14: 911.50222
A15: ΓΑΡΝΙΤΟΥΡΕΣ | C15: 6981.6757 | F15: 3497.0196 | J15: 3497.0196 | N15: 10478.695
A16: ΒΟΗΘ. ΖΑΧΑΡΟΠΛΑΣΤΙΚΗΣ ΜΑΓΕΙΡΙΚΗΣ | C16: 37.702222 | E16: 169.68 | F16: 339.36 | J16: 509.04 | K16: 401.41194 | L16: 794.10139 | M16: 1195.5133 | N16: 1742.2556
A17: ΤΟΜΑΤΟΕΙΔΗ | C17: 122.356 | N17: 122.356
A18: CARTE DOR BUFFET | C18: 6959.1162 | N18: 6959.1162
A19: ΕΠΙΔΟΡΠΙΑ | B19: 1063.94 | C19: 2899.2451 | N19: 3963.1851
A20: ΣΙΡΟΠΙΑ | C20: 2269.2677 | E20: 496.1484 | J20: 496.1484 | N20: 2765.4161
A21: LIPTON ΤΣΑΪ | B21: 0 | C21: 178.75167 | D21: 73.858535 | E21: 523.19623 | F21: 420.45171 | H21: 3.3398148 | I21: 343.97074 | J21: 1364.817 | N21: 1543.5687
A22: LIPTON ΠΥΡΑΜΙΔΑ | B22: 0 | C22: 231.55237 | D22: 183.27286 | J22: 183.27286 | N22: 414.82523
A23: Grand Total | B23: 8106.0106 | C23: 56813.713 | D23: 1689.9073 | E23: 1189.0246 | F23: 4604.3073 | G23: 762.45608 | H23: 3.3398148 | I23: 343.97074 | J23: 8593.0059 | K23: 401.41194 | L23: 794.10139 | M23: 1195.5133 | N23: 74708.243

Sheet ObsRiskPivot
A1: Material | B1: (All)
A3: Category | B3: Description | C3: Batch | D3: Unrestricted stock | E3: Stock Days | F3: Days till SSL | G3: Sum of Final Obsolete Risk | H3: Cost of Risk (standard price)
A4: ΖΩΜΟΙ | B4: KN BOU FO LIQ SHELFISH 6X1L BOT ES IT GR | D4: 98 | E4: 98 | F4: 744 | G4: 33 | H4: 1032.84
B5: KN BOUIL BEEF 1X3.5KG BUC EB PL GR HU-s | D5: 382 | E5: 75 | F5: 2704 | G5: 61 | H5: 454.03463
B6: KN BOUILLON MUSHROOM 6X500G ECO EB IT GR | D6: 10 | E6: 10 | F6: 348 | G6: 0 | H6: 0
B7: KN DSO BROTH VEG 6X1.15KG ECO EB IT GR | D7: 83 | E7: 21 | F7: 1995 | G7: 13 | H7: 138.01794
B8: KN DSO CHICKEN BROTH 6X1KG ECO EB GR | D8: 129 | E8: 43 | F8: 1348 | G8: 36 | H8: 732.48
B9: KN FOND FISH PASTY 3X1KG ECO EB AT-r | D9: 0 | E9: 0 | F9: 450 | G9: 0 | H9: 0
B10: KN PAS BOUI CHICK 1X3.5KG BUC EB GR DS | D10: 1003 | E10: 55 | F10: 5091 | G10: 51 | H10: 313.59365
B11: KN PAS BOUIL BEEF 1X4KG BUC EB GR | D11: 502 | E11: 33 | F11: 3701 | G11: 30 | H11: 337.20308
B12: KN PAS BOUIL BEEF 6X1.2KG ECO EB GR | D12: 173 | E12: 173 | F12: 2186 | G12: 128 | H12: 2649.7727
B13: KN PAS BOUIL CHICKEN 1X4KG BUC EB GR | D13: 2274 | E13: 76 | F13: 12858 | G13: 72 | H13: 421.77021
B14: KN PAS BOUIL CHICKEN 6X1.2KG ECO EB GR | D14: 313 | E14: 56 | F14: 3870 | G14: 53 | H14: 582.10422
B15: KN PAS BOUIL VEGETABLE 1X4KG BUC EB GR | D15: 1999 | E15: 45 | F15: 10320 | G15: 43 | H15: 310.98641
B16: KN PAS BOUIL VEGETABLE 6X1.2KG ECO EB GR | D16: 663 | E16: 162 | F16: 7349 | G16: 151 | H16: 2546.6655
... B18: KNORROX PAS BOUIL CHICKE 1X7KG BUC EB GR | D18: 1278 | E18: 58 | F18: 8970 | G18: 53 | H18: 456.07386
B19: KN PROF FOND LQ SHELLFIS 8X1L BRI EB EUR | C19: 0345S3K54 | D19: 40 | E19: 40 | F19: 429 | G19: 2 | H19: 77.544
B20: KN PROF FOND LQ VEAL 8X1L BRI EB EUR | C20: 1134S3K54 | D20: 6 | E20: 6 | F20: 203 | G20: 0 | H20: 0
C21: 1084S3K54 | D21: 14 | E21: 14 | F21: 500 | G21: 10 | H21: 298.528
B22: KN PROF FOND LQ CHICKEN 8X1L BRI EB EUR | C22: 1098S3K54 | D22: 22 | E22: 22 | F22: 157 | G22: 0 | H22: 0
C23: 112683K54 | D23: 20 | E23: 20 | F23: 185 | G23: 20 | H23: 605.47
C24: 114783K54 | D24: 10 | E24: 10 | F24: 206 | G24: 10 | H24: 302.74
B25: KN GF REG BOUIL CHICKEN 2X800G JAR DACH | C25: 11730039 | D25: 0 | E25: 0 | F25: 265 | G25: 0 | H25: 0
C26: 117300N39 | D26: 517 | E26: 517 | F26: 530 | G26: 252 | H26: 2815.4613
B27: KNORROX PAS BOUIL BEEF 1X7KG BUC EB GR | C27: 11860Z098 | D27: 224 | E27: 224 | F27: 1856 | G27: 180 | H27: 3105.9731
C28: 11660Z098 | D28: 44 | E28: 44 | F28: 888 | G28: 21 | H28: 362.36
A29: ΤΟΜΑΤΟΕΙΔΗ | B29: KN FINE CHOPPED TOMATO 6X2.5KG POU EB GR | D29: 421 | E29: 13 | F29: 3912 | G29: 13 | H29: 122.356
A30: SEASONINGS | B30: KN AROMAT 6X500G ECO EB IT GR | D30: 743 | E30: 60 | F30: 4656 | G30: 57 | H30: 484.64121
B31: KN PRIM BASIL 2X340G POT EB IT/GR | D31: 456 | E31: 16 | F31: 1225 | G31: 15 | H31: 50.9558
B32: KN PRIM GARLIC 2X340G POT EB IT/GR | D32: 1066 | E32: 213 | F32: 920 | G32: 137 | H32: 438.75733
B33: KN PRIM PESTO 2X340G POT EB GR | D33: 457 | E33: 114 | F33: 528 | G33: 18 | H33: 89.127188
B34: KN PRIM ROSEMARY 2X340G POT EB IT/GR | D34: 630 | E34: 316 | F34: 915 | G34: 142 | H34: 590.63413
B35: KN PRIM THYME 2X340G POT EB IT/GR | D35: 696 | E35: 37 | F35: 1225 | G35: 25 | H35: 117.24854
A36: ΣΙΡΟΠΙΑ | B36: CDO TOPPI FOREST FRUI 6X1KG BOT EB IT GR | D36: 251 | E36: 251 | F36: 938 | G36: 151 | H36: 1890.4747
B37: CDO TOPPIN STRAWBERRY 6X1KG BOT EB IT GR | D37: 151 | E37: 76 | F37: 766 | G37: 26 | H37: 315.003
B38: CDO TOPPING CHOCOLATE 6X1KG BOT EB IT GR | D38: 58 | E38: 10 | F38: 1548 | G38: 7 | H38: 63.79
B39: CDO TOPPING TOFFEE 6X1KG BOT EB IT GR | D39: 254 | E39: 84 | F39: 1707 | G39: 51 | H39: 496.1484
B40: CDO TOPPING HAZELNUT 6X1KG BOT EB IT GR | C40: 109710M95 | D40: 30 | E40: 30 | F40: 515 | G40: 0 | H40: 0
A41: ΣΑΛΤΣΕΣ | B41: KN DEMI GLACE 6X1.2KG ECO EB GR | D41: 493 | E41: 250 | F41: 4230 | G41: 224 | H41: 5066.2055
B42: KN DES 4 CHEESE 6X775G ECO EB EU | D42: 42 | E42: 42 | F42: 490 | G42: 3 | H42: 106.86
...

Sheet Stock
A1: Out of Stock Ind. | B1: Material Code | C1: Material Description | D1: Unrestricted Stock | E1: Cust.Conf.Total Qty | F1: Quantities on Deliveries | G1: Available Quantity | H1: Quality Inspection Stock | I1: Cust.Ord.Total Qty | J1: Goods Receipts Total Qty
B2: 64897767 | C2: KN GRN PEPPE DES 6x1.2KG ECO EB BENEGRIT | D2: 107 | E2: 0 | F2: 1 | G2: 106 | H2: 0 | I2: 0 | J2: 0
B3: 64902224 | C3: MAIL MUST ORIG 8x1KG BUC EB NDC IT PT GR | D3: 129 | E3: 0 | F3: 1 | G3: 128 | H3: 0 | I3: 0 | J3: 0
B4: 31132401 | C4: HLMNS MILD MUSTARD 12X500G BOT EB GR | D4: 1176 | E4: 4 | F4: 86 | G4: 1086 | H4: 0 | I4: 35 | J4: 432
B5: 69732307 | C5: HLMNS KETCHUP 12x540G SQ EB GR | D5: 2690 | E5: 0 | F5: 32 | G5: 2658 | H5: 0 | I5: 32 | J5: 0
B6: 12100503 | C6: HLMNS REAL MAYONNAISE 1X10L BUC EB GR | D6: 12420 | E6: 606 | F6: 423 | G6: 11391 | H6: 0 | I6: 736 | J6: 720
B7: 12110903 | C7: HLMNS MUSTARD SAUCE 1X3L BUC EB GR | D7: 1035 | E7: 4 | F7: 5 | G7: 1026 | H7: 0 | I7: 9 | J7: 0
B8: 12886101 | C8: HLMNS SD CITRUS 6X1L BOT EB IT | D8: 2190 | E8: 289 | F8: 38 | G8: 1863 | H8: 0 | I8: 296 | J8: 1152
B9: 28000701 | C9: HLMNS SLDDRE CAESAR 3x3L BUC EW GR | D9: 5121 | E9: 246 | F9: 298 | G9: 4577 | H9: 0 | I9: 282 | J9: 252
B10: 36010201 | C10: HLMNS KETCHUP 3X4.8KG BOT EB GR | D10: 4539 | E10: 55 | F10: 183 | G10: 4301 | H10: 0 | I10: 169 | J10: 0
B11: 62748741 | C11: HLM Proffesional mayo 1x5LBUC EB EUROPE | D11: 3843 | E11: 0 | F11: 35 | G11: 3808 | H11: 0 | I11: 230 | J11: 0
B12: 62751906 | C12: HLM Real Mayo 1x2L BUC EB DK FI GR NO SE | D12: 3670 | E12: 32 | F12: 62 | G12: 3576 | H12: 0 | I12: 32 | J12: 0
B13: 64308055 | C13: HL Vgan May 1x3L BUC EB BGESGRHRHUPTROSI | D13: 3885 | E13: 4 | F13: 46 | G13: 3835 | H13: 0 | I13: 34 | J13: 0
... B91: 81334801 | C91: KN PRIM ROAST ONION 2X340G GLA EB IT | D91: 1108 | E91: 0 | F91: 2 | G91: 1106 | H91: 0 | I91: 0 | J91: 0

Sheet S1P
A1: A/A | B1: Key | C1: Date | D1: Material | E1: Description | F1: Plant | G1: Storage location | H1: Batch | I1: Unrestricted stock | J1: Restricted stock | K1: Blocked stock | L1: Quality inspection stock | M1: Unit of measure | N1: Batch shelf life expiration date | O1: Short shelf life date | P1: Days till expired | Q1: Days till SSL | R1: SSCC | S1: Goods Receipt Date | T1: Reason code | U1: Reason Description | V1: Total-Quantity | W1: Total-Value | X1: Total-Paletts | Y1: Material Type | Z1: Idoc-Nr. | AA1: Advance warning time in days | AB1: Remaining life period | AC1: Segment-Nr. | AD1: Validity flag | AE1: Error Message | AF1: Production Date | AG1: Palletization Date | AH1: Average Sales H2 2024 | AI1: Stock Days | AJ1: Calc Days | AK1: Obsolete Risk | AL1: Final Obsolete Risk | AM1: Cost of Risk (standard price) | AN1: Category
A2: {=1+SUMPRODUCT(--(D2>$D$2:$D$826))} -> 1 | B2: =D2&A2 -> 111407041 | C2: 46008 | D2: 11140704 | E2: KNORR DSO ONION 6X565G ECO EB FRGRIT | F2: A912 | G2: 1000 | H2: 528820C93 | I2: 20 | J2: 0 | K2: 0 | L2: 0 | M2: ZUN | N2: 46507 | O2: 46427 | P2: 499 | Q2: 419 | R2: 359485176007043213 | S2: 45945 | V2: 20 | W2: 311.03 | X2: 0.444 | Y2: FERT | Z2: 2732873326 | AA2: 0 | AB2: 0 | AC2: 0 | AD2: X | AF2: 45945 | AH2: =_xlfn.IFNA(IF(VLOOKUP(D2,'Cases2021 2022 FC'!AC:AE,3,0)=0,"1",VLOOKUP(D2,'Cases2021 2022 FC'!AC:AE,3,0)),"1") -> 2 | AI2: =ROUND(I2/AH2,0) -> 10 | AJ2: =IF(Q2-AI2<0,Q2-AI2,0) -> 0 | AK2: =IF((AI2>Q2),(K2/AH2)-Q2,0)+IFERROR(IF(B2=B1,AI1,0),0) -> 0 | AL2: =IF(AK2>K2,I2,AK2) -> 0 | AM2: =IFERROR((W2/K2)*AL2,0) -> 0 | AN2: =VLOOKUP(D2,SOP!C:R,16,0) -> ΣΟΥΠΕΣ
A3: {=1+SUMPRODUCT(--(D3>$D$2:$D$826))} -> 1 | B3: =D3&A3 -> 111407041 | C3: 46008 | D3: 11140704 | E3: KNORR DSO ONION 6X565G ECO EB FRGRIT | F3: A912 | G3: 1000 | H3: 528820C93 | I3: 45 | J3: 0 | K3: 0 | L3: 0 | M3: ZUN | N3: 46507 | O3: 46427 | P3: 499 | Q3: 419 | R3: 359485176007043244 | S3: 45945 | V3: 45 | W3: 699.81 | X3: 1 | Y3: FERT | Z3: 2732873326 | AA3: 0 | AB3: 0 | AC3: 0 | AD3: X | AF3: 45945 | AH3: =_xlfn.IFNA(IF(VLOOKUP(D3,'Cases2021 2022 FC'!AC:AE,3,0)=0,"1",VLOOKUP(D3,'Cases2021 2022 FC'!AC:AE,3,0)),"1") -> 2 | AI3: =ROUND(I3/AH3,0) -> 23 | AJ3: =IF(Q3-AI3<0,Q3-AI3,0) -> 0 | AK3: =IF((AI3>Q3),(K3/AH3)-Q3,0)+IFERROR(IF(B3=B2,AI2,0),0) -> 10 | AL3: =IF(AK3>K3,I3,AK3) -> 45 | AM3: =IFERROR((W3/K3)*AL3,0) -> 0 | AN3: =VLOOKUP(D3,SOP!C:R,16,0) -> ΣΟΥΠΕΣ
A4: {=1+SUMPRODUCT(--(D4>$D$2:$D$826))} -> 1 | B4: =D4&A4 -> 111407041 | C4: 46008 | D4: 11140704 | E4: KNORR DSO ONION 6X565G ECO EB FRGRIT | F4: A912 | G4: 1000 | H4: 528820C93 | I4: 45 | J4: 0 | K4: 0 | L4: 0 | M4: ZUN | N4: 46507 | O4: 46427 | P4: 499 | Q4: 419 | R4: 359485176007043312 | S4: 45945 | V4: 45 | W4: 699.81 | X4: 1 | Y4: FERT | Z4: 2732873326 | AA4: 0 | AB4: 0 | AC4: 0 | AD4: X | AF4: 45945 | AH4: =_xlfn.IFNA(IF(VLOOKUP(D4,'Cases2021 2022 FC'!AC:AE,3,0)=0,"1",VLOOKUP(D4,'Cases2021 2022 FC'!AC:AE,3,0)),"1") -> 2 | AI4: =ROUND(I4/AH4,0) -> 23 | AJ4: =IF(Q4-AI4<0,Q4-AI4,0) -> 0 | AK4: =IF((AI4>Q4),(K4/AH4)-Q4,0)+IFERROR(IF(B4=B3,AI3,0),0) -> 23 | AL4: =IF(AK4>K4,I4,AK4) -> 45 | AM4: =IFERROR((W4/K4)*AL4,0) -> 0 | AN4: =VLOOKUP(D4,SOP!C:R,16,0) -> ΣΟΥΠΕΣ
A5: {=1+SUMPRODUCT(--(D5>$D$2:$D$826))} -> 1 | B5: =D5&A5 -> 111407041 | C5: 46008 | D5: 11140704 | E5: KNORR DSO ONION 6X565G ECO EB FRGRIT | F5: A912 | G5: 1000 | H5: 528820C93 | I5: 45 | J5: 0 | K5: 0 | L5: 0 | M5: ZUN | N5: 46507 | O5: 46427 | P5: 499 | Q5: 419 | R5: 359485176007043350 | S5: 45945 | V5: 45 | W5: 699.81 | X5: 1 | Y5: FERT | Z5: 2732873326 | AA5: 0 | AB5: 0 | AC5: 0 | AD5: X | AF5: 45945 | AH5: =_xlfn.IFNA(IF(VLOOKUP(D5,'Cases2021 2022 FC'!AC:AE,3,0)=0,"1",VLOOKUP(D5,'Cases2021 2022 FC'!AC:AE,3,0)),"1") -> 2 | AI5: =ROUND(I5/AH5,0) -> 23 | AJ5: =IF(Q5-AI5<0,Q5-AI5,0) -> 0 | AK5: =IF((AI5>Q5),(K5/AH5)-Q5,0)+IFERROR(IF(B5=B4,AI4,0),0) -> 23 | AL5: =IF(AK5>K5,I5,AK5) -> 45 | AM5: =IFERROR((W5/K5)*AL5,0) -> 0 | AN5: =VLOOKUP(D5,SOP!C:R,16,0) -> ΣΟΥΠΕΣ
A6: {=1+SUMPRODUCT(--(D6>$D$2:$D$826))} -> 5 | B6: =D6&A6 -> 112471035 | C6: 46008 | D6: 11247103 | E6: KN COUS COUS TABOULE 6X625G PK EB GR IT | F6: A912 | G6: 1000 | H6: 512416C93 | I6: 45 | J6: 0 | K6: 0 | L6: 0 | M6: ZUN | N6: 46356 | O6: 46296 | P6: 348 | Q6: 288 | R6: 359485176005993640 | S6: 45811 | V6: 45 | W6: 895.82 | X6: 1 | Y6: FERT | Z6: 2732873326 | AA6: 0 | AB6: 0 | AC6: 0 | AD6: X | AF6: 45781 | AH6: =_xlfn.IFNA(IF(VLOOKUP(D6,'Cases2021 2022 FC'!AC:AE,3,0)=0,"1",VLOOKUP(D6,'Cases2021 2022 FC'!AC:AE,3,0)),"1") -> 2 | AI6: =ROUND(I6/AH6,0) -> 23 | AJ6: =IF(Q6-AI6<0,Q6-AI6,0) -> 0 | AK6: =IF((AI6>Q6),(K6/AH6)-Q6,0)+IFERROR(IF(B6=B5,AI5,0),0) -> 0 | AL6: =IF(AK6>K6,I6,AK6) -> 0 | AM6: =IFERROR((W6/K6)*AL6,0) -> 0 | AN6: =VLOOKUP(D6,SOP!C:R,16,0) -> ΓΑΡΝΙΤΟΥΡΕΣ
A7: {=1+SUMPRODUCT(--(D7>$D$2:$D$826))} -> 5 | B7: =D7&A7 -> 112471035 | C7: 46008 | D7: 11247103 | E7: KN COUS COUS TABOULE 6X625G PK EB GR IT | F7: A912 | G7: 1000 | H7: 512416C93 | I7: 29 | J7: 0 | K7: 0 | L7: 0 | M7: ZUN | N7: 46356 | O7: 46296 | P7: 348 | Q7: 288 | R7: 359485176005993657 | S7: 45811 | V7: 29 | W7: 577.31 | X7: 0.644 | Y7: FERT | Z7: 2732873326 | AA7: 0 | AB7: 0 | AC7: 0 | AD7: X | AF7: 45781 | AH7: =_xlfn.IFNA(IF(VLOOKUP(D7,'Cases2021 2022 FC'!AC:AE,3,0)=0,"1",VLOOKUP(D7,'Cases2021 2022 FC'!AC:AE,3,0)),"1") -> 2 | AI7: =ROUND(I7/AH7,0) -> 15 | AJ7: =IF(Q7-AI7<0,Q7-AI7,0) -> 0 | AK7: =IF((AI7>Q7),(K7/AH7)-Q7,0)+IFERROR(IF(B7=B6,AI6,0),0) -> 23 | AL7: =IF(AK7>K7,I7,AK7) -> 29 | AM7: =IFERROR((W7/K7)*AL7,0) -> 0 | AN7: =VLOOKUP(D7,SOP!C:R,16,0) -> ΓΑΡΝΙΤΟΥΡΕΣ
A8: {=1+SUMPRODUCT(--(D8>$D$2:$D$826))} -> 5 | B8: =D8&A8 -> 112471035 | C8: 46008 | D8: 11247103 | E8: KN COUS COUS TABOULE 6X625G PK EB GR IT | F8: A912 | G8: 1000 | H8: 512416C93 | I8: 45 | J8: 0 | K8: 0 | L8: 0 | M8: ZUN | N8: 46356 | O8: 46296 | P8: 348 | Q8: 288 | R8: 359485176005993664 | S8: 45811 | V8: 45 | W8: 895.82 | X8: 1 | Y8: FERT | Z8: 2732873326 | AA8: 0 | AB8: 0 | AC8: 0 | AD8: X | AF8: 45781 | AH8: =_xlfn.IFNA(IF(VLOOKUP(D8,'Cases2021 2022 FC'!AC:AE,3,0)=0,"1",VLOOKUP(D8,'Cases2021 2022 FC'!AC:AE,3,0)),"1") -> 2 | AI8: =ROUND(I8/AH8,0) -> 23 | AJ8: =IF(Q8-AI8<0,Q8-AI8,0) -> 0 | AK8: =IF((AI8>Q8),(K8/AH8)-Q8,0)+IFERROR(IF(B8=B7,AI7,0),0) -> 15 | AL8: =IF(AK8>K8,I8,AK8) -> 45 | AM8: =IFERROR((W8/K8)*AL8,0) -> 0 | AN8: =VLOOKUP(D8,SOP!C:R,16,0) -> ΓΑΡΝΙΤΟΥΡΕΣ
A9: {=1+SUMPRODUCT(--(D9>$D$2:$D$826))} -> 5 | B9: =D9&A9 -> 112471035 | C9: 46008 | D9: 11247103 | E9: KN COUS COUS TABOULE 6X625G PK EB GR IT | F9: A912 | G9: 1000 | H9: 512416C93 | I9: 45 | J9: 0 | K9: 0 | L9: 0 | M9: ZUN | N9: 46356 | O9: 46296 | P9: 348 | Q9: 288 | R9: 359485176005993695 | S9: 45811 | V9: 45 | W9: 895.82 | X9: 1 | Y9: FERT | Z9: 2732873326 | AA9: 0 | AB9: 0 | AC9: 0 | AD9: X | AF9: 45781 | AH9: =_xlfn.IFNA(IF(VLOOKUP(D9,'Cases2021 2022 FC'!AC:AE,3,0)=0,"1",VLOOKUP(D9,'Cases2021 2022 FC'!AC:AE,3,0)),"1") -> 2 | AI9: =ROUND(I9/AH9,0) -> 23 | AJ9: =IF(Q9-AI9<0,Q9-AI9,0) -> 0 | AK9: =IF((AI9>Q9),(K9/AH9)-Q9,0)+IFERROR(IF(B9=B8,AI8,0),0) -> 23 | AL9: =IF(AK9>K9,I9,AK9) -> 45 | AM9: =IFERROR((W9/K9)*AL9,0) -> 0 | AN9: =VLOOKUP(D9,SOP!C:R,16,0) -> ΓΑΡΝΙΤΟΥΡΕΣ
A10: {=1+SUMPRODUCT(--(D10>$D$2:$D$826))} -> 5 | B10: =D10&A10 -> 112471035 | C10: 46008 | D10: 11247103 | E10: KN COUS COUS TABOULE 6X625G PK EB GR IT | F10: A912 | G10: 1000 | H10: 512416C93 | I10: 45 | J10: 0 | K10: 0 | L10: 0 | M10: ZUN | N10: 46356 | O10: 46296 | P10: 348 | Q10: 288 | R10: 359485176005993701 | S10: 45811 | V10: 45 | W10: 895.82 | X10: 1 | Y10: FERT | Z10: 2732873326 | AA10: 0 | AB10: 0 | AC10: 0 | AD10: X | AF10: 45781 | AH10: =_xlfn.IFNA(IF(VLOOKUP(D10,'Cases2021 2022 FC'!AC:AE,3,0)=0,"1",VLOOKUP(D10,'Cases2021 2022 FC'!AC:AE,3,0)),"1") -> 2 | AI10: =ROUND(I10/AH10,0) -> 23 | AJ10: =IF(Q10-AI10<0,Q10-AI10,0) -> 0 | AK10: =IF((AI10>Q10),(K10/AH10)-Q10,0)+IFERROR(IF(B10=B9,AI9,0),0) -> 23 | AL10: =IF(AK10>K10,I10,AK10) -> 45 | AM10: =IFERROR((W10/K10)*AL10,0) -> 0 | AN10: =VLOOKUP(D10,SOP!C:R,16,0) -> ΓΑΡΝΙΤΟΥΡΕΣ
A11: {=1+SUMPRODUCT(--(D11>$D$2:$D$826))} -> 5 | B11: =D11&A11 -> 112471035 | C11: 46008 | D11: 11247103 | E11: KN COUS COUS TABOULE 6X625G PK EB GR IT | F11: A912 | G11: 1000 | H11: 512416C93 | I11: 45 | J11: 0 | K11: 0 | L11: 0 | M11: ZUN | N11: 46356 | O11: 46296 | P11: 348 | Q11: 288 | R11: 359485176005993718 | S11: 45811 | V11: 45 | W11: 895.82 | X11: 1 | Y11: FERT | Z11: 2732873326 | AA11: 0 | AB11: 0 | AC11: 0 | AD11: X | AF11: 45781 | AH11: =_xlfn.IFNA(IF(VLOOKUP(D11,'Cases2021 2022 FC'!AC:AE,3,0)=0,"1",VLOOKUP(D11,'Cases2021 2022 FC'!AC:AE,3,0)),"1") -> 2 | AI11: =ROUND(I11/AH11,0) -> 23 | AJ11: =IF(Q11-AI11<0,Q11-AI11,0) -> 0 | AK11: =IF((AI11>Q11),(K11/AH11)-Q11,0)+IFERROR(IF(B11=B10,AI10,0),0) -> 23 | AL11: =IF(AK11>K11,I11,AK11) -> 45 | AM11: =IFERROR((W11/K11)*AL11,0) -> 0 | AN11: =VLOOKUP(D11,SOP!C:R,16,0) -> ΓΑΡΝΙΤΟΥΡΕΣ
A12: {=1+SUMPRODUCT(--(D12>$D$2:$D$826))} -> 5 | B12: =D12&A12 -> 112471035 | C12: 46008 | D12: 11247103 | E12: KN COUS COUS TABOULE 6X625G PK EB GR IT | F12: A912 | G12: 1000 | H12: 512416C93 | I12: 45 | J12: 0 | K12: 0 | L12: 0 | M12: ZUN | N12: 46356 | O12: 46296 | P12: 348 | Q12: 288 | R12: 359485176005994265 | S12: 45811 | V12: 45 | W12: 895.82 | X12: 1 | Y12: FERT | Z12: 2732873326 | AA12: 0 | AB12: 0 | AC12: 0 | AD12: X | AF12: 45781 | AH12: =_xlfn.IFNA(IF(VLOOKUP(D12,'Cases2021 2022 FC'!AC:AE,3,0)=0,"1",VLOOKUP(D12,'Cases2021 2022 FC'!AC:AE,3,0)),"1") -> 2 | AI12: =ROUND(I12/AH12,0) -> 23 | AJ12: =IF(Q12-AI12<0,Q12-AI12,0) -> 0 | AK12: =IF((AI12>Q12),(K12/AH12)-Q12,0)+IFERROR(IF(B12=B11,AI11,0),0) -> 23 | AL12: =IF(AK12>K12,I12,AK12) -> 45 | AM12: =IFERROR((W12/K12)*AL12,0) -> 0 | AN12: =VLOOKUP(D12,SOP!C:R,16,0) -> ΓΑΡΝΙΤΟΥΡΕΣ
A13: {=1+SUMPRODUCT(--(D13>$D$2:$D$826))} -> 5 | B13: =D13&A13 -> 112471035 | C13: 46008 | D13: 11247103 | E13: KN COUS COUS TABOULE 6X625G PK EB GR IT | F13: A912 | G13: 1000 | H13: 512416C93 | I13: 45 | J13: 0 | K13: 0 | L13: 0 | M13: ZUN | N13: 46356 | O13: 46296 | P13: 348 | Q13: 288 | R13: 359485176005994272 | S13: 45811 | V13: 45 | W13: 895.82 | X13: 1 | Y13: FERT | Z13: 2732873326 | AA13: 0 | AB13: 0 | AC13: 0 | AD13: X | AF13: 45781 | AH13: =_xlfn.IFNA(IF(VLOOKUP(D13,'Cases2021 2022 FC'!AC:AE,3,0)=0,"1",VLOOKUP(D13,'Cases2021 2022 FC'!AC:AE,3,0)),"1") -> 2 | AI13: =ROUND(I13/AH13,0) -> 23 | AJ13: =IF(Q13-AI13<0,Q13-AI13,0) -> 0 | AK13: =IF((AI13>Q13),(K13/AH13)-Q13,0)+IFERROR(IF(B13=B12,AI12,0),0) -> 23 | AL13: =IF(AK13>K13,I13,AK13) -> 45 | AM13: =IFERROR((W13/K13)*AL13,0) -> 0 | AN13: =VLOOKUP(D13,SOP!C:R,16,0) -> ΓΑΡΝΙΤΟΥΡΕΣ
... A1126: {=1+SUMPRODUCT(--(D1126>$D$2:$D$826))} -> 826 | B1126: =D1126&A1126 -> 81334801826 | C1126: 46008 | D1126: 81334801 | E1126: KN PRIM ROAST ONION 2X340G GLA EB IT | F1126: A912 | G1126: 1000 | H1126: 516100N39 | I1126: 1 | J1126: 0 | K1126: 0 | L1126: 0 | M1126: ZUN | N1126: 46203 | O1126: 46143 | P1126: 195 | Q1126: 135 | R1126: 635201028263357625 | S1126: 45832 | V1126: 1 | W1126: 3.77 | X1126: 0.003 | Y1126: FERT | Z1126: 2732873326 | AA1126: 0 | AB1126: 0 | AC1126: 0 | AD1126: X | AF1126: 45818 | AH1126: =_xlfn.IFNA(IF(VLOOKUP(D1126,'Cases2021 2022 FC'!AC:AE,3,0)=0,"1",VLOOKUP(D1126,'Cases2021 2022 FC'!AC:AE,3,0)),"1") -> 2 | AI1126: =ROUND(I1126/AH1126,0) -> 1 | AJ1126: =IF(Q1126-AI1126<0,Q1126-AI1126,0) -> 0 | AK1126: =IF((AI1126>Q1126),(K1126/AH1126)-Q1126,0)+IFERROR(IF(B1126=B1125,AI1125,0),0) -> 183 | AL1126: =IF(AK1126>K1126,I1126,AK1126) -> 1 | AM1126: =IFERROR((W1126/K1126)*AL1126,0) -> 0 | AN1126: =VLOOKUP(D1126,SOP!C:R,16,0) -> SEASONINGS

Sheet Top10
A1: TOP10 DESCRIPTION | B1: MRDR | C1: ΠΕΡΙΓΡΑΦΗ | D1: Status
A2: Hellmans 5lt & 10lt | B2: 22100403 | C2: HLMNS ΜΑΓΙΟΝΕΖΑ REAL 5Λ | D2: =VLOOKUP(B2,SOP!C:J,4,0) -> #N/A
B3: 12101903 | C3: HLMNS ΜΑΓΙΟΝΕΖΑ REAL 5Λ+500ML ΔΩΡΟ | D3: =VLOOKUP(B3,SOP!C:J,4,0) -> #N/A
B4: 12100503 | C4: HLMNS ΜΑΓΙΟΝΕΖΑ REAL 10Λ | D4: =VLOOKUP(B4,SOP!C:J,4,0)
A5: CDO CAKE 5KG, 10KG & 20KG | B5: 67512459 | C5: CDO ΚΕΙΚ ΜΕ ΓΕΥΣΗ ΒΑΝΙΛΙΑΣ 1X20KG | D5: =VLOOKUP(B5,SOP!C:J,4,0)
B6: 67512406 | C6: CDO ΚΕΙΚ ΜΕ ΓΕΥΣΗ ΚΑΚΑΟ 1X20KG | D6: =VLOOKUP(B6,SOP!C:J,4,0)
B7: 67830533 | C7: CDO ΚΕΙΚ ΜΕ ΓΕΥΣΗ ΒΑΝΙΛΙΑΣ 1X5KG | D7: =VLOOKUP(B7,SOP!C:J,4,0) -> #N/A
B8: 67830530 | C8: CDO ΚΕΙΚ ΜΕ ΓΕΥΣΗ ΚΑΚΑΟ 1X5KG | D8: =VLOOKUP(B8,SOP!C:J,4,0) -> #N/A
A9: HELLMANN'S CAESAR'S | B9: 28000701 | C9: HELLMANN'S ΝΤΡΕΣΙΝΓΚ ΣΙΖΑΡ 3x3 ΛΙΤ | D9: =VLOOKUP(B9,SOP!C:J,4,0) -> OOS Risk
A10: HLMNS MAYO LIGHT 1X5 | B10: 13217307 | C10: HELLMANNS ΑΝΑΠΛΗΡΩΜΑ ΜΑΓΙΟΝΕΖΑΣ 1Χ5Λ | D10: =VLOOKUP(B10,SOP!C:J,4,0) -> #N/A
A11: Kn Pas Bouil Chicken 4kg & 1.2kg | B11: 12011702 | C11: KNORR ΖΩΜΟΣ ΚΟΤΑΣ 1*4Κ | D11: =VLOOKUP(B11,SOP!C:J,4,0)
B12: 39631001 | C12: KNORR ΖΩΜΟΣ ΚΟΤΑΣ 6*1,2Κ | D12: =VLOOKUP(B12,SOP!C:J,4,0)
A13: Knorr Demi Glace | B13: 67738206 | C13: KNORR ΣΑΛΤΣΑ ΝΤΕΜΙ ΓΚΛΑΣ 6Χ1,2 ΚΙΛ | D13: =VLOOKUP(B13,SOP!C:J,4,0)
B14: 67738211 | C14: KNORR ΣΑΛΤΣΑ ΝΤΕΜΙ ΓΚΛΑΣ 1Χ4 ΚΙΛ | D14: =VLOOKUP(B14,SOP!C:J,4,0)
A15: KNORROX PAS BOUIL CHICKE 1X7KG BUC EL GR | B15: 22010602 | C15: KNORROX ΖΩΜΟΣ ΚΟΤΑΣ 1x7 ΚΙΛ. | D15: =VLOOKUP(B15,SOP!C:J,4,0)
A16: LIPTON YELLOW LABEL 100CSEX12 EU | B16: 67578611 | C16: LIPTON ΜΑΥΡΟ ΤΣΑΙ ΚΙΤΡ ΦΑΚ 12Χ100Χ1,5ΓΡ | D16: =VLOOKUP(B16,SOP!C:J,4,0) -> #N/A
A17: Portion Packs | B17: 67682357 | C17: HELLMANN'S ΜΕΡΙΔΕΣ ΜΑΓΙΟΝΕΖΑΣ 198x10ML | D17: =VLOOKUP(B17,SOP!C:J,4,0)
B18: 67682359 | C18: HELLMANN'S ΜΕΡΙΔΕΣ ΚΕΤΣΑΠ 198x10ML | D18: =VLOOKUP(B18,SOP!C:J,4,0)
B19: 67969831 | C19: HELLMANN'S ΜΕΡΙΔΕΣ ΜΠΑΡΜΠΕΚΙΟΥ 198x10ML | D19: =VLOOKUP(B19,SOP!C:J,4,0)
B20: 67682348 | C20: HELLMANN'S ΜΕΡΙΔΕΣ ΜΟΥΣΤΑΡΔΑΣ 198x10ML | D20: =VLOOKUP(B20,SOP!C:J,4,0)
A21: Hellmann's BBQ | B21: 67291280 | C21: HELLMANN'S ΣΑΛΤΣΑ ΓΙΑ ΜΠΑΡΜΠΕΚΙΟΥ 3Χ4,8 ΚΙΛ. | D21: =VLOOKUP(B21,SOP!C:J,4,0) -> #N/A

Sheet SOP
D1: Link to Top 10 | H1: 20 | L1: =TODAY() -> 46021
K2: Supply Chain Input
A3: Κατηγορία | B3: Trade | C3: MRDR | D3: ΠΕΡΙΓΡΑΦΗ ΠΡΟΪΟΝΤΟΣ | F3: Status | G3: Average Sales per day (2025 FC Q3) | H3: Stock Days | I3: Days till Availability | J3: Available Stock | K3: Exptected Quantity | L3: Scheduled Delivery Date | M3: Expected Cases | N3: Comments | O3: Status SC | P3: Batch shelf life expiration date
A4: DRESSINGS | B4: 64324731 | C4: 64324731 | D4: HELLMANN’S ΝΤΡΕΣΙΝΓΚ CLASSIC 6x1Λ | F4: =IF(H4=0,"OOS",IF(H4<=10,"OOS Risk","")) | G4: =_xlfn.IFNA(IF(VLOOKUP(C4,'Cases2021 2022 FC'!AC:AD,2,0)=0,"1",VLOOKUP(C4,'Cases2021 2022 FC'!AC:AD,2,0)),1) -> 2 | H4: =ROUND(J4/G4,0) -> 94 | I4: =IFERROR(IF(L4="",0,L4-$L$1)-1,0) -> 0 | J4: =SUMIF(S1P!D:K,C:C,S1P!I:KI) -> 188 | K4: 0 | L4: TBC | O4: =IF(H4=0,"OOS",IF(H4<=10,"OOS Risk",IF(H4<=20,"SC Input",""))) | P4: =_xlfn.IFNA(VLOOKUP(C4,S1P!D:N,11,0),"") -> 46155 | R4: =A4 -> DRESSINGS
A5: CARTE DOR BUFFET | B5: 67512327 | C5: 67512327 | D5: CDO ΜΕΙΓΜΑ ΓΙΑ CRÈME CARAMEL/BRULEE1X10KG | F5: =IF(H5=0,"OOS",IF(H5<=10,"OOS Risk","")) | G5: =_xlfn.IFNA(IF(VLOOKUP(C5,'Cases2021 2022 FC'!AC:AD,2,0)=0,"1",VLOOKUP(C5,'Cases2021 2022 FC'!AC:AD,2,0)),1) -> 1 | H5: =ROUND(J5/G5,0) -> 60 | I5: =IFERROR(IF(L5="",0,L5-$L$1)-0.0001,0) -> 0 | J5: =SUMIF(S1P!D:K,C:C,S1P!I:KI) -> 60 | K5: 0 | L5: TBC | M5: 56 | O5: =IF(H5=0,"OOS",IF(H5<=10,"OOS Risk",IF(H5<=20,"SC Input",""))) | P5: =_xlfn.IFNA(VLOOKUP(C5,S1P!D:N,5,0),"") -> 325062401 | R5: =A5 -> CARTE DOR BUFFET
A6: DRESSINGS | B6: 64315194 | C6: 64315194 | D6: HELLMANN’S ΝΤΡΕΣΙΝΓΚ CHIV&PARSL 6x1Λ | F6: =IF(H6=0,"OOS",IF(H6<=10,"OOS Risk","")) -> OOS | G6: =_xlfn.IFNA(IF(VLOOKUP(C6,'Cases2021 2022 FC'!AC:AD,2,0)=0,"1",VLOOKUP(C6,'Cases2021 2022 FC'!AC:AD,2,0)),1) -> 1 | H6: =ROUND(J6/G6,0) -> 0 | I6: =IFERROR(IF(L6="",0,L6-$L$1)-0.0001,0) -> 0 | J6: =SUMIF(S1P!D:K,C:C,S1P!I:KI) -> 0 | K6: 300 | L6: TBC | M6: =K6 -> 300 | N6: prod in wk02. Couldn't be handle in december due to limited capacity at SU | O6: =IF(H6=0,"OOS",IF(H6<=10,"OOS Risk",IF(H6<=20,"SC Input",""))) -> OOS | P6: =_xlfn.IFNA(VLOOKUP(C6,S1P!D:N,11,0),"") | R6: =A6 -> DRESSINGS
A7: CARTE DOR BUFFET | B7: 67830539 | C7: 67830539 | D7: CDO ΜΟΥΣ ΜΕ ΓΕΥΣΗ ΒΑΝΙΛΙΑΣ 1X5KG | F7: =IF(H7=0,"OOS",IF(H7<=10,"OOS Risk","")) | G7: =_xlfn.IFNA(IF(VLOOKUP(C7,'Cases2021 2022 FC'!AC:AD,2,0)=0,"1",VLOOKUP(C7,'Cases2021 2022 FC'!AC:AD,2,0)),1) -> 1 | H7: =ROUND(J7/G7,0) -> 103 | I7: =IFERROR(IF(L7="",0,L7-$L$1)-1,0) -> 0 | J7: =SUMIF(S1P!D:K,C:C,S1P!I:KI) -> 103 | K7: 0 | L7: TBC | M7: 55 | O7: =IF(H7=0,"OOS",IF(H7<=10,"OOS Risk",IF(H7<=20,"SC Input",""))) | P7: =_xlfn.IFNA(VLOOKUP(C7,S1P!D:N,11,0),"") -> 46253 | R7: =A7 -> CARTE DOR BUFFET
A8: CARTE DOR BUFFET | B8: 67512194 | C8: 67512194 | D8: CDO ΜΕΙΓΜΑ ΓΙΑ PANNA COTTA 1X10KG | F8: =IF(H8=0,"OOS",IF(H8<=10,"OOS Risk","")) | G8: =_xlfn.IFNA(IF(VLOOKUP(C8,'Cases2021 2022 FC'!AC:AD,2,0)=0,"1",VLOOKUP(C8,'Cases2021 2022 FC'!AC:AD,2,0)),1) -> 1 | H8: =ROUND(J8/G8,0) -> 32 | I8: =IFERROR(IF(L8="",0,L8-$L$1)-1,0) -> 0 | J8: =SUMIF(S1P!D:K,C:C,S1P!I:KI) -> 32 | K8: 0 | L8: TBC | M8: 112 | O8: =IF(H8=0,"OOS",IF(H8<=10,"OOS Risk",IF(H8<=20,"SC Input",""))) | P8: =_xlfn.IFNA(VLOOKUP(C8,S1P!D:N,11,0),"") -> 46253 | R8: =A8 -> CARTE DOR BUFFET
A9: DRESSINGS | B9: 67751022 | C9: 67751022 | D9: HLMNS ΣΑΛΤΣΑ DELUXE ΓΙΑ ΠΑΤΑΤ. 6Χ850ΓΡ | F9: =IF(H9=0,"OOS",IF(H9<=10,"OOS Risk","")) | G9: =_xlfn.IFNA(IF(VLOOKUP(C9,'Cases2021 2022 FC'!AC:AD,2,0)=0,"1",VLOOKUP(C9,'Cases2021 2022 FC'!AC:AD,2,0)),1) -> 4 | H9: =ROUND(J9/G9,0) -> 164 | I9: =IFERROR(IF(L9="",0,L9-$L$1)-0.0001,0) -> 0 | J9: =SUMIF(S1P!D:K,C:C,S1P!I:KI) -> 657 | K9: 0 | L9: TBC | O9: =IF(H9=0,"OOS",IF(H9<=10,"OOS Risk",IF(H9<=20,"SC Input",""))) | P9: =_xlfn.IFNA(VLOOKUP(C9,S1P!D:N,11,0),"") -> 46142 | R9: =A9 -> DRESSINGS
A10: CARTE DOR BUFFET | B10: 68222641 | C10: 68222641 | D10: CDO ΜΕΙΓΜΑ ΓΙΑ ΠΑΝΚΕΪΚ/ΒΑΦΛΑ 6X2KG | F10: =IF(H10=0,"OOS",IF(H10<=10,"OOS Risk","")) | G10: =_xlfn.IFNA(IF(VLOOKUP(C10,'Cases2021 2022 FC'!AC:AD,2,0)=0,"1",VLOOKUP(C10,'Cases2021 2022 FC'!AC:AD,2,0)),1) -> 1 | H10: =ROUND(J10/G10,0) -> 110 | I10: =IFERROR(IF(L10="",0,L10-$L$1)-0.0001,0) -> 0 | J10: =SUMIF(S1P!D:K,C:C,S1P!I:KI) -> 110 | K10: 0 | L10: TBC | O10: =IF(H10=0,"OOS",IF(H10<=10,"OOS Risk",IF(H10<=20,"SC Input",""))) | P10: =_xlfn.IFNA(VLOOKUP(C10,S1P!D:N,11,0),"") -> 46233 | R10: =A10 -> CARTE DOR BUFFET
A11: CARTE DOR BUFFET | B11: 67512459 | C11: 67512459 | D11: CDO ΚΕΙΚ ΜΕ ΓΕΥΣΗ ΒΑΝΙΛΙΑΣ 1X20KG | E11: Top 10 | F11: =IF(H11=0,"OOS",IF(H11<=10,"OOS Risk","")) | G11: =_xlfn.IFNA(IF(VLOOKUP(C11,'Cases2021 2022 FC'!AC:AD,2,0)=0,"1",VLOOKUP(C11,'Cases2021 2022 FC'!AC:AD,2,0)),1) -> 1 | H11: =ROUND(J11/G11,0) -> 100 | I11: =IFERROR(IF(L11="",0,L11-$L$1)-0.0001,0) -> 0 | J11: =SUMIF(S1P!D:K,C:C,S1P!I:KI) -> 100 | K11: 0 | L11: TBC | O11: =IF(H11=0,"OOS",IF(H11<=10,"OOS Risk",IF(H11<=20,"SC Input",""))) | P11: =_xlfn.IFNA(VLOOKUP(C11,S1P!D:N,11,0),"") -> 46227 | R11: =A11 -> CARTE DOR BUFFET
A12: DRESSINGS | B12: 68429197 | C12: 68429197 | D12: HELLMANN'S ΝΤΡΕΣΙΝΓΚ ΜΕΛΙ & ΜΟΥΣΤΑΡΔΑ 6x1 ΛΙΤ | F12: =IF(H12=0,"OOS",IF(H12<=10,"OOS Risk","")) | G12: =_xlfn.IFNA(IF(VLOOKUP(C12,'Cases2021 2022 FC'!AC:AD,2,0)=0,"1",VLOOKUP(C12,'Cases2021 2022 FC'!AC:AD,2,0)),1) -> 54 | H12: =ROUND(J12/G12,0) -> 14 | I12: =IFERROR(IF(L12="",0,L12-$L$1)-1,0) -> 0 | J12: =SUMIF(S1P!D:K,C:C,S1P!I:KI) -> 744 | L12: TBC | M12: =K12 -> 0 | O12: =IF(H12=0,"OOS",IF(H12<=10,"OOS Risk",IF(H12<=20,"SC Input",""))) -> SC Input | P12: =_xlfn.IFNA(VLOOKUP(C12,S1P!D:N,11,0),"") -> 46252 | R12: =A12 -> DRESSINGS
A13: CARTE DOR BUFFET | B13: 67512406 | C13: 67512406 | D13: CDO ΚΕΙΚ ΜΕ ΓΕΥΣΗ ΚΑΚΑΟ 1X20KG | E13: Top 10 | F13: =IF(H13=0,"OOS",IF(H13<=10,"OOS Risk","")) | G13: =_xlfn.IFNA(IF(VLOOKUP(C13,'Cases2021 2022 FC'!AC:AD,2,0)=0,"1",VLOOKUP(C13,'Cases2021 2022 FC'!AC:AD,2,0)),1) -> 1 | H13: =ROUND(J13/G13,0) -> 41 | I13: =IFERROR(IF(L13="",0,L13-$L$1)-0.0001,0) -> 0 | J13: =SUMIF(S1P!D:K,C:C,S1P!I:KI) -> 41 | K13: 0 | L13: TBC | O13: =IF(H13=0,"OOS",IF(H13<=10,"OOS Risk",IF(H13<=20,"SC Input",""))) | P13: =_xlfn.IFNA(VLOOKUP(C13,S1P!D:N,11,0),"") -> 46162 | R13: CARTE DOR BUFFET
A14: SEASONINGS | B14: T20325 | C14: 17193301 | D14: KNORR PRIMERBA ΠΑΣΤΑ ΘΥΜΑΡΙ 2×340 ΓΡ. | F14: =IF(H14=0,"OOS",IF(H14<=10,"OOS Risk","")) | G14: =_xlfn.IFNA(IF(VLOOKUP(C14,'Cases2021 2022 FC'!AC:AD,2,0)=0,"1",VLOOKUP(C14,'Cases2021 2022 FC'!AC:AD,2,0)),1) -> 54 | H14: =ROUND(J14/G14,0) -> 51 | I14: =IFERROR(IF(L14="",0,L14-$L$1)-0.0001,0) -> 0 | J14: =SUMIF(S1P!D:K,C:C,S1P!I:KI) -> 2770 | K14: 3675 | L14: TBC | M14: =K14 -> 3675 | O14: =IF(H14=0,"OOS",IF(H14<=10,"OOS Risk",IF(H14<=20,"SC Input",""))) | P14: =_xlfn.IFNA(VLOOKUP(C14,S1P!D:N,11,0),"") -> 46326 | R14: =A14 -> SEASONINGS
A15: WORLD CUISINES | B15: 67262258 | C15: 67262258 | D15: KN ΠΙΚΑΝΤ.ΣΑΛΤΣΑ ΜΕ ΤΣΙΛΙ,TOMATA 6Χ1ΛΤ | F15: =IF(H15=0,"OOS",IF(H15<=10,"OOS Risk","")) | G15: =_xlfn.IFNA(IF(VLOOKUP(C15,'Cases2021 2022 FC'!AC:AD,2,0)=0,"1",VLOOKUP(C15,'Cases2021 2022 FC'!AC:AD,2,0)),1) -> 1 | H15: =ROUND(J15/G15,0) -> 71 | I15: =IFERROR(IF(L15="",0,L15-$L$1)-0.0001,0) -> 0 | J15: =SUMIF(S1P!D:K,C:C,S1P!I:KI) -> 71 | K15: 80 | L15: TBC | M15: =K15 -> 80 | N15: Delivery was planned fo 04.11.2025 but don't arrive. Im checking this with Dispatch planner. | O15: =IF(H15=0,"OOS",IF(H15<=10,"OOS Risk",IF(H15<=20,"SC Input",""))) | P15: =_xlfn.IFNA(VLOOKUP(C15,S1P!D:N,11,0),"") -> 46205 | R15: =A15 -> WORLD CUISINES
A16: CARTE DOR BUFFET | B16: 67830541 | C16: 67830541 | D16: CDO ΜΟΥΣ ΜΕ ΓΕΥΣΗ ΣΟΚΟΛΑΤΑΣ 1X5KG | F16: =IF(H16=0,"OOS",IF(H16<=10,"OOS Risk","")) | G16: =_xlfn.IFNA(IF(VLOOKUP(C16,'Cases2021 2022 FC'!AC:AD,2,0)=0,"1",VLOOKUP(C16,'Cases2021 2022 FC'!AC:AD,2,0)),1) -> 1 | H16: =ROUND(J16/G16,0) -> 76 | I16: =IFERROR(IF(L16="",0,L16-$L$1)-0.0001,0) -> 0 | J16: =SUMIF(S1P!D:K,C:C,S1P!I:KI) -> 76 | K16: 0 | L16: TBC | O16: =IF(H16=0,"OOS",IF(H16<=10,"OOS Risk",IF(H16<=20,"SC Input",""))) | P16: =_xlfn.IFNA(VLOOKUP(C16,S1P!D:N,11,0),"") -> 46253 | R16: =A16 -> CARTE DOR BUFFET
A17: WORLD CUISINES | B17: 67418234 | C17: 67418234 | D17: ΚΝΟRR ΣΑΛΤΣΑ ΤΕΡΙΓΙΑΚΙ 6x1,23ΚΙΛ | F17: =IF(H17=0,"OOS",IF(H17<=10,"OOS Risk","")) -> OOS | G17: =_xlfn.IFNA(IF(VLOOKUP(C17,'Cases2021 2022 FC'!AC:AD,2,0)=0,"1",VLOOKUP(C17,'Cases2021 2022 FC'!AC:AD,2,0)),1) -> 1 | H17: =ROUND(J17/G17,0) -> 0 | I17: =IFERROR(IF(L17="",0,L17-$L$1)-0.0001,0) -> -8.0001 | J17: =SUMIF(S1P!D:K,C:C,S1P!I:KI) -> 0 | K17: 80 | L17: 46013 | M17: =K17 -> 80 | O17: =IF(H17=0,"OOS",IF(H17<=10,"OOS Risk",IF(H17<=20,"SC Input",""))) -> OOS | P17: =_xlfn.IFNA(VLOOKUP(C17,S1P!D:N,11,0),"") | R17: =A17 -> WORLD CUISINES
